Workbook
Name CIQWBGuid: "2cd8126d-26c3-430c-b7fa-a069e3a1fc62"
Name IQ_CH: 110000
Name IQ_CQ: 5000
Name IQ_CY: 10000
Name IQ_DAILY: 500000
Name IQ_DNTM: 700000
Name IQ_FH: 100000
Name IQ_FQ: 500
Name IQ_FWD_CY: 10001
Name IQ_FWD_CY1: 10002
Name IQ_FWD_CY2: 10003
Name IQ_FWD_FY: 1001
Name IQ_FWD_FY1: 1002
Name IQ_FWD_FY2: 1003
Name IQ_FWD_Q: 501
Name IQ_FWD_Q1: 502
Name IQ_FWD_Q2: 503
Name IQ_FY: 1000
Name IQ_LATESTK: 1000
Name IQ_LATESTQ: 500
Name IQ_LTM: 2000
Name IQ_LTMMONTH: 120000
Name IQ_MONTH: 15000
Name IQ_MTD: 800000
Name IQ_NAMES_REVISION_DATE_: "10/01/2018 15:52:08"
Name IQ_NTM: 6000
Name IQ_QTD: 750000
Name IQ_TODAY: 0
Name IQ_WEEK: 50000
Name IQ_YTD: 3000
Name IQ_YTDMONTH: 130000
Name UPDATE: '[1]Data Sheet'!$E$1
Name UPDATE: '[1]Data Sheet'!$E$1
Name UPDATE: 'Data Sheet'!$E$1

Sheet Model

Sheet 3 STATEMENT MODEL
B1: 3-Statement Model
B2: ='Data Sheet'!B1 -> ITC LTD
E4: Historical Results | J4: Forecast Period
E5: 2021 | F5: =+E5+1 -> 2022 | G5: =+F5+1 -> 2023 | H5: =+G5+1 -> 2024 | I5: =+H5+1 -> 2025 | J5: 2026E | K5: 2027E | L5: 2028E | M5: 2029E | N5: 2030E
B7: Assumptions
B9: Key Assumptions
B10: Revenue Growth (% Change) | F10: =F28/E28-1 -> 0.23117498 | G10: =G28/F28-1 -> 0.16942152 | H10: =H28/G28-1 -> -0.042119724 | I10: =I28/H28-1 -> 0.10880596 | J10: ='Revenue CAGR'!D31 -> 0.10294052 | K10: =J10 -> 0.10294052 | L10: =K10 -> 0.10294052 | M10: =L10 -> 0.10294052 | N10: =M10 -> 0.10294052
B11: Cost of Goods Sold (% of Revenue) | E11: =E29/E28 -> 0.45512263 | F11: =F29/F28 -> 0.4808761 | G11: =G29/G28 -> 0.45919847 | H11: =H29/H28 -> 0.44334756 | I11: =I29/I28 -> 0.46863867 | J11: ='Cost Assumptions'!D16 -> 0.43731074 | K11: =J11 -> 0.43731074 | L11: =K11 -> 0.43731074 | M11: =L11 -> 0.43731074 | N11: =M11 -> 0.43731074
B12: Salaries and Benefits (% of Revenue) | E12: =E34/E28 -> 0.17662506 | F12: =F34/F28 -> 0.16075528 | G12: =G34/G28 -> 0.15990489 | H12: =H34/H28 -> 0.15988032 | I12: =I34/I28 -> 0.15882288 | J12: ='Cost Assumptions'!D28 -> 0.16319769 | K12: =J12 -> 0.16319769 | L12: =K12 -> 0.16319769 | M12: =L12 -> 0.16319769 | N12: =M12 -> 0.16319769
B13: Other Expenses | E13: =E35 -> 1074.39 | F13: =F35 -> 1109.95 | G13: =G35 -> 1308.56 | H13: =H35 -> 1765.97 | I13: =I35 -> 2221.39 | J13: =I13*(1+'Cost Assumptions'!$D$40) -> 2488.7685 | K13: =J13*(1+'Cost Assumptions'!$D$40) -> 2788.33 | L13: =K13*(1+'Cost Assumptions'!$D$40) -> 3123.9484 | M13: =L13*(1+'Cost Assumptions'!$D$40) -> 3499.9637 | N13: =M13*(1+'Cost Assumptions'!$D$40) -> 3921.2381
B14: Other Income | E14: =E31 -> 2576.95 | F14: =F31 -> 1909.72 | G14: =G31 -> 2097.64 | H14: =H31 -> 3330.45 | I14: =I31 -> 3454 | J14: =I14*(1+'Other Key Assumptions'!$F$18) -> 3744.1876 | K14: =J14*(1+'Other Key Assumptions'!$F$18) -> 4058.7552 | L14: =K14*(1+'Other Key Assumptions'!$F$18) -> 4399.7513 | M14: =L14*(1+'Other Key Assumptions'!$F$18) -> 4769.3961 | N14: =M14*(1+'Other Key Assumptions'!$F$18) -> 5170.0966
B15: Depreciation & Amortization (% of PP&E) | E15: =E36/E50 -> 0.059538695 | F15: =F36/F50 -> 0.057799019 | G15: =G36/G50 -> 0.055947609 | H15: =H36/H50 -> 0.042353942 | I15: =I36/I50 -> 0.056673896 | J15: ='Cost Assumptions'!D49 -> 0.048174657 | K15: =J15 -> 0.048174657 | L15: =K15 -> 0.048174657 | M15: =L15 -> 0.048174657 | N15: =M15 -> 0.048174657
B16: Interest (% of Debt) | E16: =E37/E58 -> 0.0063738318 | F16: =F37/F58 -> 0.0058112952 | G16: =G37/G58 -> 0.0064722037 | H16: =H37/H58 -> 0.0031413655 | I16: =I37/I58 -> 0.0034227117 | J16: ='Cost Assumptions'!D87 -> 0.15461797 | K16: =J16 -> 0.15461797 | L16: =K16 -> 0.15461797 | M16: =L16 -> 0.15461797 | N16: =M16 -> 0.15461797
B17: Tax Rate (% of Earnings Before Tax) | E17: =E41/E39 -> 0.25394396 | F17: =F41/F39 -> 0.2525179 | G17: =G41/G39 -> 0.24844184 | H17: =H41/H39 -> 0.23031421 | I17: =I41/I39 -> 0.24963599 | J17: 0.28 | K17: 0.28 | L17: 0.28 | M17: 0.28 | N17: 0.28
B18: Accounts Receivable (Days) | E18: ='Balance Sheet'!G20 -> 18.537714 | F18: ='Balance Sheet'!H20 -> 14.817385 | G18: ='Balance Sheet'!I20 -> 15.214563 | H18: ='Balance Sheet'!J20 -> 21.630831 | I18: ='Balance Sheet'!K20 -> 22.870462 | J18: ='Other Key Assumptions'!F4 -> 18.614191 | K18: =J18 -> 18.614191 | L18: =K18 -> 18.614191 | M18: =L18 -> 18.614191 | N18: =M18 -> 18.614191
B19: Inventory (Days) | E19: ='Other Key Assumptions'!J4 -> 130.86912 | F19: ='Other Key Assumptions'!K4 -> 113.94539 | G19: ='Other Key Assumptions'!L4 -> 107.85155 | H19: ='Other Key Assumptions'!M4 -> 132.65123 | I19: ='Other Key Assumptions'!N4 -> 131.10342 | J19: ='Other Key Assumptions'!J4 -> 130.86912 | K19: =J19 -> 130.86912 | L19: =K19 -> 130.86912 | M19: =L19 -> 130.86912 | N19: =M19 -> 130.86912
B20: Accounts Payable (Days) | E20: ='Other Key Assumptions'!J5 -> 70.319491 | F20: ='Other Key Assumptions'!K5 -> 55.283479 | G20: ='Other Key Assumptions'!L5 -> 52.218255 | H20: ='Other Key Assumptions'!M5 -> 58.147998 | I20: ='Other Key Assumptions'!N5 -> 49.70491 | J20: ='Other Key Assumptions'!F6 -> 53.838661 | K20: =J20 -> 53.838661 | L20: =K20 -> 53.838661 | M20: =L20 -> 53.838661 | N20: =M20 -> 53.838661
B21: Capital Expenditures ($000's) | E21: ='Cost Assumptions'!J67 -> 1834 | F21: ='Cost Assumptions'!K67 -> 2009 | G21: ='Cost Assumptions'!L67 -> 2694 | H21: ='Cost Assumptions'!M67 -> 3456 | I21: ='Cost Assumptions'!N67 -> 2104 | J21: ='Cost Assumptions'!J71 -> 3109.6572 | K21: ='Cost Assumptions'!K71 -> 3429.767 | L21: ='Cost Assumptions'!L71 -> 3782.8289 | M21: ='Cost Assumptions'!M71 -> 4172.2353 | N21: ='Cost Assumptions'!N71 -> 4601.7274
B22: Debt Issuance (Repayment) ($000's) | E22: =E92 -> -2 | F22: =F92 -> -1 | G22: =G92 -> -1 | H22: =H92 -> 6 | I22: =I92 -> 88 | J22: =-$I$22*'Cost Assumptions'!$D$99 -> -13.2 | K22: =-$I$22*'Cost Assumptions'!$D$99 -> -13.2 | L22: =-$I$22*'Cost Assumptions'!$D$99 -> -13.2 | M22: =-$I$22*'Cost Assumptions'!$D$99 -> -13.2 | N22: =-$I$22*'Cost Assumptions'!$D$99 -> -13.2
B23: Equity Issued (Repaid) ($000's) | E23: =E93 -> 291 | F23: =F93 -> 292 | G23: =G93 -> 2477 | H23: =H93 -> 1443 | I23: =I93 -> 797 | J23: 0 | K23: 0 | L23: 0 | M23: 0 | N23: 0
B24: Days in Period | E24: 365 | F24: 365 | G24: 365 | H24: 365 | I24: 365 | J24: 365 | K24: 365 | L24: 365 | M24: 365 | N24: 365
B26: Income Statement
B28: Revenue | E28: ='Data Sheet'!G17 -> 49257.45 | F28: ='Data Sheet'!H17 -> 60644.54 | G28: ='Data Sheet'!I17 -> 70919.03 | H28: ='Data Sheet'!J17 -> 67931.94 | I28: ='Data Sheet'!K17 -> 75323.34 | J28: =I28*(1+J10) -> 83077.164 | K28: =J28*(1+K10) -> 91629.17 | L28: =K28*(1+L10) -> 101061.52 | M28: =L28*(1+M10) -> 111464.85 | N28: =M28*(1+N10) -> 122939.1
B29: Cost of Goods Sold (COGS) | E29: ='Data Sheet'!G18+SUM('Data Sheet'!G20:G21)-'Data Sheet'!G19 -> 22418.18 | F29: ='Data Sheet'!H18+SUM('Data Sheet'!H20:H21)-'Data Sheet'!H19 -> 29162.51 | G29: ='Data Sheet'!I18+SUM('Data Sheet'!I20:I21)-'Data Sheet'!I19 -> 32565.91 | H29: ='Data Sheet'!J18+SUM('Data Sheet'!J20:J21)-'Data Sheet'!J19 -> 30117.46 | I29: ='Data Sheet'!K18+SUM('Data Sheet'!K20:K21)-'Data Sheet'!K19 -> 35299.43 | J29: =J28*J11 -> 36330.536 | K29: =K28*K11 -> 40070.42 | L29: =L28*L11 -> 44195.29 | M29: =M28*M11 -> 48744.776 | N29: =N28*N11 -> 53762.588
B30: Gross Profit | E30: =E28-E29 -> 26839.27 | F30: =F28-F29 -> 31482.03 | G30: =G28-G29 -> 38353.12 | H30: =H28-H29 -> 37814.48 | I30: =I28-I29 -> 40023.91 | J30: =J28-J29 -> 46746.628 | K30: =K28-K29 -> 51558.75 | L30: =L28-L29 -> 56866.234 | ... N30: =N28-N29 -> 69176.51
B31: Other Income | E31: ='Data Sheet'!G25 -> 2576.95 | F31: ='Data Sheet'!H25 -> 1909.72 | G31: ='Data Sheet'!I25 -> 2097.64 | H31: ='Data Sheet'!J25 -> 3330.45 | I31: ='Data Sheet'!N27 -> 3454 | J31: =J14 -> 3744.1876 | K31: =K14 -> 4058.7552 | L31: =L14 -> 4399.7513 | M31: =M14 -> 4769.3961 | N31: =N14 -> 5170.0966
B33: Expenses
B34: Salaries and Benefits | E34: =SUM('Data Sheet'!G22:G23) -> 8700.1 | F34: =SUM('Data Sheet'!H22:H23) -> 9748.93 | G34: =SUM('Data Sheet'!I22:I23) -> 11340.3 | H34: =SUM('Data Sheet'!J22:J23) -> 10860.98 | I34: =SUM('Data Sheet'!K22:K23) -> 11963.07 | J34: =J12*J28 -> 13558.001 | K34: =K12*K28 -> 14953.669 | L34: =L12*L28 -> 16493.007 | M34: =M12*M28 -> 18190.806 | N34: =N12*N28 -> 20063.376
B35: Other Expenses | E35: ='Data Sheet'!G24 -> 1074.39 | F35: ='Data Sheet'!H24 -> 1109.95 | G35: ='Data Sheet'!I24 -> 1308.56 | H35: ='Data Sheet'!J24 -> 1765.97 | I35: ='Data Sheet'!K24 -> 2221.39 | J35: =J13 -> 2488.7685 | K35: =K13 -> 2788.33 | L35: =L13 -> 3123.9484 | M35: =M13 -> 3499.9637 | N35: =N13 -> 3921.2381
B36: Depreciation & Amortization | E36: ='Data Sheet'!G26 -> 1645.59 | F36: ='Data Sheet'!H26 -> 1732.41 | G36: ='Data Sheet'!I26 -> 1809.01 | H36: ='Data Sheet'!J26 -> 1518.05 | I36: ='Data Sheet'!K26 -> 1646.32 | J36: =J77 -> 1511.9433 | K36: =K77 -> 1588.9126 | L36: =L77 -> 1677.5951 | M36: =M77 -> 1779.0141 | N36: =N77 -> 1894.3067
B37: Interest | E37: ='Data Sheet'!G27 -> 57.97 | F37: ='Data Sheet'!H27 -> 59.99 | G37: ='Data Sheet'!I27 -> 77.77 | H37: ='Data Sheet'!J27 -> 39.11 | I37: ='Data Sheet'!K27 -> 45.06 | J37: =J125 -> 43.6 | K37: =K125 -> 43.6 | L37: =L125 -> 43.6 | M37: =M125 -> 43.6 | N37: =N125 -> 43.6
B38: Total Expenses | E38: =SUM(E34:E37) -> 11478.05 | F38: =SUM(F34:F37) -> 12651.28 | G38: =SUM(G34:G37) -> 14535.64 | H38: =SUM(H34:H37) -> 14184.11 | I38: =SUM(I34:I37) -> 15875.84 | J38: =SUM(J34:J37) -> 17602.313 | K38: =SUM(K34:K37) -> 19374.511 | L38: =SUM(L34:L37) -> 21338.15 | ... N38: =SUM(N34:N37) -> 25922.521
B39: Earnings Before Tax | E39: =SUM(E30:E31)-E38 -> 17938.17 | F39: =SUM(F30:F31)-F38 -> 20740.47 | G39: =SUM(G30:G31)-G38 -> 25915.12 | H39: =SUM(H30:H31)-H38 -> 26960.82 | I39: =SUM(I30:I31)-I38 -> 27602.07 | J39: =SUM(J30:J31)-J38 -> 32888.503 | K39: =SUM(K30:K31)-K38 -> 36242.994 | L39: =SUM(L30:L31)-L38 -> 39927.835 | ... N39: =SUM(N30:N31)-N38 -> 48424.086
B41: Taxes | E41: ='Data Sheet'!G29 -> 4555.29 | F41: ='Data Sheet'!H29 -> 5237.34 | G41: ='Data Sheet'!I29 -> 6438.4 | H41: ='Data Sheet'!J29 -> 6209.46 | I41: ='Data Sheet'!K29 -> 6890.47 | J41: =J39*J17 -> 9208.7807 | K41: =K39*K17 -> 10148.038 | L41: =L39*L17 -> 11179.794 | M41: =M39*M17 -> 12313.304 | N41: =N39*N17 -> 13558.744
B42: Net Earnings | E42: =E39-E41 -> 13382.88 | F42: =F39-F41 -> 15503.13 | G42: =G39-G41 -> 19476.72 | H42: =H39-H41 -> 20751.36 | I42: =I39-I41 -> 20711.6 | J42: =J39-J41 -> 23679.722 | K42: =K39-K41 -> 26094.955 | L42: =L39-L41 -> 28748.041 | ... N42: =N39-N41 -> 34865.342
B44: Balance Sheet
B46: Assets
B47: Cash | E47: ='Data Sheet'!G69 -> 4659.02 | F47: ='Data Sheet'!H69 -> 4654.42 | G47: ='Data Sheet'!I69 -> 4880.19 | H47: ='Data Sheet'!J69 -> 7217.68 | I47: ='Data Sheet'!K69 -> 4012.36 | J47: =J101 -> 19622.897 | K47: =K101 -> 26725.145 | L47: =L101 -> 36455.817 | M47: =M101 -> 49077.636 | N47: =N101 -> 64879.425
B48: Accounts Receivable | E48: ='Data Sheet'!G67 -> 2501.7 | F48: ='Data Sheet'!H67 -> 2461.9 | G48: ='Data Sheet'!I67 -> 2956.17 | H48: ='Data Sheet'!J67 -> 4025.82 | I48: ='Data Sheet'!K67 -> 4719.67 | J48: =J28*J18/J24 -> 4236.7512 | K48: =K28*K18/K24 -> 4672.8845 | L48: =L28*L18/L24 -> 5153.9137 | M48: =M28*M18/M24 -> 5684.4602 | N48: =N28*N18/N24 -> 6269.6215
B49: Inventory | E49: ='Data Sheet'!G68 -> 10397.16 | F49: ='Data Sheet'!H68 -> 10864.15 | G49: ='Data Sheet'!I68 -> 11771.16 | H49: ='Data Sheet'!J68 -> 14152.88 | I49: ='Data Sheet'!K68 -> 15637.56 | J49: =J29*J19/J24 -> 13026.151 | K49: =K29*K19/K24 -> 14367.07 | L49: =L29*L19/L24 -> 15846.023 | M49: =M29*M19/M24 -> 17477.221 | N49: =N29*N19/N24 -> 19276.335
...

Sheet Key Assumptions

Sheet Revenue CAGR
B2: Key Assumption Rates
B3: ITC LTD
B6: Revenue
B7: Sector Reports
B8: Based only on tobacco sector | L8: from | M8: to
A9: 1 | B9: imarc | C9: CAGR | D9: 0.021 | L9: 2025 | M9: 2033
A10: 2 | B10: Statista | C10: CAGR | D10: 0.0422 | L10: 2025 | M10: NA
A11: 3 | B11: wrightresearch | C11: CAGR | D11: 0.043162731 | L11: 2025 | M11: 2029
L12: 14.01 | M12: 16.59
B14: Equity Reports
A15: 1 | B15: ICICI | C15: CAGR | D15: 0.073999534 | L15: 2025 | M15: 2026 | N15: 2027
A16: 2 | B16: nuvama | C16: CAGR | D16: 0.10362187 | L16: 0.067 | M16: 0.073 | N16: 0.075 | P16: 100
C17: CAGR | D17: 0.149
A18: 3 | B18: Axis | C18: CAGR | D18: 0.10041664 | L18: 106.7 | M18: 114.4891 | N18: 123.07578
A19: 4 | B19: Deven Choksey | C19: CAGR | D19: 0.114
A20: 5 | B20: Mirae Asset | C20: CAGR | D20: =_xlfn.RRI(2,L29,N29) -> 0.090121265
B22: Analyst Forecasts
A23: 1 | B23: Trendlyne | C23: CAGR | D23: =_xlfn.RRI(2,L26,N26) -> 0.089378447 | E23: Neutral | L23: 75323 | M23: 84276 | N23: 91742
C24: CAGR | D24: =_xlfn.RRI(2,L27,N27) -> 0.13339462 | E24: Bullish | L24: 70900 | M24: 78000 | N24: 85854
C25: CAGR | D25: =_xlfn.RRI(2,L28,N28) -> 0.061472795 | E25: Bearish
L26: 70600.4 | M26: 76381.8 | N26: 83784.7
B27: Historic Rate - 5Y CAGR | L27: 70600.4 | M27: 79571.5 | N27: 90692.1
A28: 1 | B28: ITC | C28: CAGR | D28: 0.114 | L28: 70600.4 | M28: 73833.2 | N28: 79547.2
L29: 70600.4 | M29: 75967 | N29: 83899
B31: Average | D31: =AVERAGE(D15:D28) -> 0.10294052
B32: Median | D32: =MEDIAN(D14:D27) -> 0.10041664

Sheet Cost Assumptions
B2: Key Assumption Rates
B3: ITC LTD
B5: Cost of Goods Sold
B6: Equity Reports
B7: ICICI | C7: % of revenue | D7: 0.445
B8: nuvama | C8: % of revenue | D8: 0.392
B10: Axis | C10: % of revenue | D10: 0.433
B12: Historic Rate - 5Y
B13: ITC | C13: % of revenue | D13: =AVERAGE('Profit & Loss'!G38:K38) -> 0.47924296
B16: Average | D16: =AVERAGE(D7:D13) -> 0.43731074
B17: Median | D17: =MEDIAN(D7:D13) -> 0.439
B19: Employee Cost
B20: Historic Rate - 5Y
B21: ITC | C21: % of revenue | D21: =AVERAGE('Profit & Loss'!G39:K39) -> 0.16319769
B23: Equity Reports
B24: ICICI | C24: % of revenue | D24: =_xlfn.RRI(2,3416.7,4021.5) -> 0.084902257
B25: Axis | C25: % of revenue | D25: =_xlfn.RRI(2,4105,4968) -> 0.10010519
B28: Best Estimate | D28: =D21 -> 0.16319769
B29: Median | D29: =MEDIAN(D21:D26) -> 0.10010519
B31: Other Expenses
C32: Increasing YoY Growth Rate
B33: Historic Rate - 5Y
B34: ITC | C34: YoY Growth | D34: =AVERAGE('Profit & Loss'!G40:K40) -> 0.13928652
B36: Equity Reports
B37: ICICI | C37: YoY Growth | D37: =_xlfn.RRI(2,10146,12774) -> 0.12205986
B38: Axis | C38: YoY Growth | D38: =_xlfn.RRI(2,10900,13183) -> 0.099749763
B40: Average | D40: =AVERAGE(D33:D38) -> 0.12036538
B41: Median | D41: =MEDIAN(D33:D38) -> 0.12205986
B47: Depreciation | G47: Non Current Assets | J47: 44256 | K47: 44621 | L47: 44986 | M47: 45352 | N47: 45717
B48: Historical Approach | G48: Land | J48: 2889 | K48: 2829 | L48: 2830 | M48: 2865 | N48: 1588
B49: Average Depreciation % Gross PPE - 5Y | D49: =AVERAGE(J62:N62) -> 0.048174657 | G49: Building | J49: 8387 | K49: 9100 | L49: 9789 | M49: 10944 | N49: 7550
B50: Average PPE % Revenue - 5Y | D50: =AVERAGE(J65:N65) -> 0.48491117 | G50: Plant Machinery | J50: 15307 | K50: 16912 | L50: 18480 | M50: 20718 | N50: 19423
B51: Average Capex % Revenue - 5Y | D51: =AVERAGE(J68:N68) -> 0.037430951 | G51: Equipments | J51: 41 | K51: 44 | L51: 44 | M51: 53 | N51: 63
G52: Furniture n fittings | J52: 833 | K52: 907 | L52: 1000 | M52: 1068 | N52: 282
G53: Railway sidings | J53: 2 | K53: 2 | L53: 2 | M53: 2 | N53: 2
G54: Vehicles | J54: 180 | K54: 179 | L54: 189 | M54: 192 | N54: 141
G55: Intangible Assets | J55: 2734 | K55: 2744 | L55: 3490 | M55: 3505 | N55: 3622
G56: Other fixed assets | J56: 716 | K56: 719 | L56: 786 | M56: 841 | N56: 967
G58: Gross Block | J58: 31089 | K58: 33436 | L58: 36610 | M58: 40188 | N58: 33638
G59: Accumulated Depreciation | J59: -7790 | K59: -9204 | L59: -10757 | M59: -12368 | N59: -11683
...

Sheet Other Key Assumptions
B2: Current Assets and Liabilities | J2: 44256 | K2: 44621 | L2: 44986 | M2: 45352 | N2: 45717
B3: Historical Approach | H3: Debtor Days | J3: ='Balance Sheet'!G20 -> 18.537714 | K3: ='Balance Sheet'!H20 -> 14.817385 | L3: ='Balance Sheet'!I20 -> 15.214563 | M3: ='Balance Sheet'!J20 -> 21.630831 | N3: ='Balance Sheet'!K20 -> 22.870462
B4: Average Debtor Days | F4: =AVERAGE(J3:N3) -> 18.614191 | H4: Inventory Days | J4: =365/('Historical FS'!H11/(('Historical FS'!H66+'Historical FS'!G66)/2)) -> 130.86912 | K4: =365/('Historical FS'!I11/(('Historical FS'!I66+'Historical FS'!H66)/2)) -> 113.94539 | L4: =365/('Historical FS'!J11/(('Historical FS'!J66+'Historical FS'!I66)/2)) -> 107.85155 | M4: =365/('Historical FS'!K11/(('Historical FS'!K66+'Historical FS'!J66)/2)) -> 132.65123 | N4: =365/('Historical FS'!L11/(('Historical FS'!L66+'Historical FS'!K66)/2)) -> 131.10342
B5: Average Inventory Days | F5: =AVERAGE(J4:N4) -> 123.28414 | H5: Payable Days | J5: 70.319491 | K5: 55.283479 | L5: 52.218255 | M5: 58.147998 | N5: 49.70491
B6: Average Payable Days - 4Y | F6: =AVERAGE(K5:N5) -> 53.838661 | H6: Payable Days | J6: =365/('3 STATEMENT MODEL'!E29/'3 STATEMENT MODEL'!E60) -> 70.319491 | K6: =365/('3 STATEMENT MODEL'!F29/'3 STATEMENT MODEL'!F60) -> 55.283479 | L6: =365/('3 STATEMENT MODEL'!G29/'3 STATEMENT MODEL'!G60) -> 52.218255 | M6: =365/('3 STATEMENT MODEL'!H29/'3 STATEMENT MODEL'!H60) -> 58.147998 | N6: =365/('3 STATEMENT MODEL'!I29/'3 STATEMENT MODEL'!I60) -> 49.70491
B8: Other Expenses
B9: Increasing YoY Growth Rate
B10: Historic Rate - 5Y
B11: ITC | C11: YoY Growth | F11: =AVERAGE('Profit & Loss'!G41:K41) -> 0.10606508
B12: ITC | C12: CAGR | F12: ='Profit & Loss'!K43 -> 0.075979719
B14: Equity Reports
B15: ICICI | C15: YoY Growth | F15: 0.07
B18: Average | F18: =AVERAGE(F11:F15) -> 0.084014931
B19: Median | F19: =MEDIAN(F11:F15) -> 0.075979719
B21: Other Liabilities
B22: Increasing YoY Growth Rate
B23: Historic Rate - 5Y
B24: ITC | C24: CAGR | F24: =_xlfn.RRI(4,'3 STATEMENT MODEL'!E57,'3 STATEMENT MODEL'!I57) -> 0.099185575
B26: Other Assets
B27: Increasing YoY Growth Rate
B28: Historic Rate - 5Y
B29: ITC | C29: CAGR | F29: =_xlfn.RRI(4,'3 STATEMENT MODEL'!E51,'3 STATEMENT MODEL'!I51) -> 0.048979954

Sheet Data Room

Sheet Data Sheet
A1: COMPANY NAME | B1: ITC LTD | E1: =IF(B2<>B3, "A NEW VERSION OF THE WORKSHEET IS AVAILABLE", "")
A2: LATEST VERSION | B2: 2.1 | E2: PLEASE DO NOT MAKE ANY CHANGES TO THIS SHEET
A3: CURRENT VERSION | B3: 2.1
A5: META
A6: Number of shares | B6: =IF(B9>0, B9/B8, 0) -> 1252.2004
A7: Face Value | B7: 1
A8: Current Price | B8: 401
A9: Market Capitalization | B9: 502132.38
A15: PROFIT & LOSS
A16: Report Date | B16: 42460 | C16: 42825 | D16: 43190 | E16: 43555 | F16: 43921 | G16: 44286 | H16: 44651 | I16: 45016 | J16: 45382 | K16: 45747
A17: Sales | B17: 39192.1 | C17: 42767.6 | D17: 43448.94 | E17: 48339.58 | F17: 49387.7 | G17: 49257.45 | H17: 60644.54 | I17: 70919.03 | J17: 67931.94 | K17: 75323.34
A18: Raw Material Cost | B18: 13763.88 | C18: 15456.59 | D18: 14827.72 | E18: 17623.52 | F18: 18048.6 | G18: 20776.71 | H18: 27071.07 | I18: 29364.36 | J18: 27348.57 | K18: 32704.37
A19: Change in Inventory | B19: 195.38 | C19: -592.57 | D19: -1027.76 | E19: 203.19 | F19: 703.13 | G19: 645.27 | H19: 686 | I19: 358.59 | J19: 367.77 | K19: 725.65
A20: Power and Fuel | B20: 571.88 | C20: 584.33 | D20: 653.5 | E20: 746.73 | F20: 780.85 | G20: 699.56 | H20: 889.77 | I20: 1232.34 | J20: 952.9 | K20: 975.35
A21: Other Mfr. Exp | B21: 1581.59 | C21: 1683.9 | D21: 1697.62 | E21: 1871.01 | F21: 1908.29 | G21: 1587.18 | H21: 1887.67 | I21: 2327.8 | J21: 2183.76 | K21: 2345.36
A22: Employee Cost | B22: 3440.97 | C22: 3631.73 | D22: 3760.9 | E22: 4177.88 | F22: 4295.79 | G22: 4463.33 | H22: 4890.55 | I22: 5736.22 | J22: 5548.53 | K22: 6169.78
A23: Selling and admin | B23: 4261.78 | C23: 4179.74 | D23: 3954.87 | E23: 4546.39 | F23: 4488.63 | G23: 4236.77 | H23: 4858.38 | I23: 5604.08 | J23: 5312.45 | K23: 5793.29
A24: Other Expenses | B24: 1235.89 | C24: 1169.23 | D24: 1005.98 | E24: 1039.85 | F24: 1225.13 | G24: 1074.39 | H24: 1109.95 | I24: 1308.56 | J24: 1765.97 | K24: 2221.39
A25: Other Income | B25: 1483.11 | C25: 1758.63 | D25: 2239.81 | E25: 2080.44 | F25: 2417.32 | G25: 2576.95 | H25: 1909.72 | I25: 2097.64 | J25: 3330.45 | K25: 17794.88 | N25: This is includes 14340 worth of exceptional one off income from discontinued operations
A26: Depreciation | B26: 1077.4 | C26: 1152.79 | D26: 1236.28 | E26: 1396.61 | F26: 1644.91 | G26: 1645.59 | H26: 1732.41 | I26: 1809.01 | J26: 1518.05 | K26: 1646.32
A27: Interest | B27: 78.13 | C27: 49.03 | D27: 115.01 | E27: 71.4 | F27: 81.38 | G27: 57.97 | H27: 59.99 | I27: 77.77 | J27: 39.11 | K27: 45.06 | N27: 3454 | O27: =K25-N27 -> 14340.88
A28: Profit before tax | B28: 14859.07 | C28: 16026.32 | D28: 17409.11 | E28: 19149.82 | F28: 20034.57 | G28: 17938.17 | H28: 20740.47 | I28: 25915.12 | J28: 26960.82 | K28: 41942.95
A29: Tax | B29: 5358.21 | C29: 5549.09 | D29: 5916.43 | E29: 6313.92 | F29: 4441.79 | G29: 4555.29 | H29: 5237.34 | I29: 6438.4 | J29: 6209.46 | K29: 6890.47
A30: Net profit | B30: 9344.45 | C30: 10289.44 | D30: 11271.2 | E30: 12592.33 | F30: 15306.23 | G30: 13161.19 | H30: 15242.66 | I30: 19191.66 | J30: 20458.78 | K30: 34746.63
A31: Dividend Amount | B31: 6840.12 | C31: 5770.02 | D31: 6285.21 | E31: 7048.7 | F31: 12476.58 | G31: 13231.96 | H31: 14171.8 | I31: 19263.4 | J31: 17166.46 | K31: 17957.73
A40: Quarters
A41: Report Date | B41: 45016 | C41: 45107 | D41: 45199 | E41: 45291 | F41: 45382 | G41: 45473 | H41: 45565 | I41: 45657 | J41: 45747 | K41: 45838
A42: Sales | B42: 17634.89 | C42: 17164.46 | D42: 17774.47 | E42: 17195.24 | F42: 17037.8 | G42: 17777.81 | H42: 19990.36 | I42: 18790.17 | J42: 18765 | K42: 21494.79
A43: Expenses | B43: 11010.89 | C43: 10494.39 | D43: 11320.23 | E43: 10985.01 | F43: 10735.73 | G43: 11232.97 | H43: 13438.28 | I43: 12428.27 | J43: 12245.61 | K43: 14678.32
A44: Other Income | B44: 682.52 | C44: 722.3 | D44: 673.5 | E44: 820.26 | F44: 868 | G44: 771.13 | H44: 690.31 | I44: 803.4 | J44: 15391.28 | K44: 750.97
A45: Depreciation | B45: 461.4 | C45: 442.46 | D45: 453.04 | E45: 384.04 | F45: 385.09 | G45: 403.13 | H45: 416.18 | I45: 415.98 | J45: 411.03 | K45: 422.96
A46: Interest | B46: 12.15 | C46: 9.9 | D46: 9.87 | E46: 11.94 | F46: 10.72 | G46: 9.6 | H46: 14.73 | I46: 9.82 | J46: 10.91 | K46: 16.47
A47: Profit before tax | B47: 6832.97 | C47: 6940.01 | D47: 6664.83 | E47: 6634.51 | F47: 6774.26 | G47: 6903.24 | H47: 6811.48 | I47: 6739.5 | J47: 21488.73 | K47: 7128.01
A48: Tax | B48: 1607.95 | C48: 1759.89 | D48: 1700.31 | E48: 1227.99 | F48: 1583.55 | G48: 1726.25 | H48: 1757.05 | I48: 1726.32 | J48: 1680.85 | K48: 1784.6
A49: Net profit | B49: 5175.48 | C49: 5104.93 | D49: 4898.07 | E49: 5335.23 | F49: 5120.55 | G49: 5091.59 | H49: 4992.87 | I49: 4934.8 | J49: 19727.37 | K49: 5244.2
A50: Operating Profit | B50: 6624 | C50: 6670.07 | D50: 6454.24 | E50: 6210.23 | F50: 6302.07 | G50: 6544.84 | H50: 6552.08 | I50: 6361.9 | J50: 6519.39 | K50: 6816.47
A55: BALANCE SHEET
A56: Report Date | B56: 42460 | C56: 42825 | D56: 43190 | E56: 43555 | F56: 43921 | G56: 44286 | H56: 44651 | I56: 45016 | J56: 45382 | K56: 45747
A57: Equity Share Capital | B57: 804.72 | C57: 1214.74 | D57: 1220.43 | E57: 1225.86 | F57: 1229.22 | G57: 1230.88 | H57: 1232.33 | I57: 1242.8 | J57: 1248.47 | K57: 1251.41
A58: Reserves | B58: 41874.8 | C58: 45198.19 | D58: 51289.68 | E58: 57915.01 | F58: 64044.04 | G58: 59116.46 | H58: 61223.24 | I58: 67912.46 | J58: 73258.53 | K58: 68778.64
...

Sheet Expanded BS
B2: Balance Sheet
C4: 44256 | D4: 44621 | E4: 44986 | F4: 45352 | G4: 45717
B5: Equity Capital | C5: 1231 | D5: 1232 | E5: 1243 | F5: 1248 | G5: 1251
B6: Reserves | C6: 59116 | D6: 61223 | E6: 67912 | F6: 73259 | G6: 68779
B7: Borrowings | K7: Borrowings | L7: 44256 | M7: 44621 | N7: 44986 | O7: 45352 | P7: 45717
B8: Long term Borrowings | C8: 6 | D8: 5 | E8: 3 | F8: 2 | G8: 0 | K8: Long term Borrowings | L8: 6 | M8: 5 | N8: 3 | O8: 2 | P8: 0
B9: Short term Borrowings | C9: 4 | D9: 1 | E9: 35 | F9: 10 | G9: 91 | K9: Short term Borrowings | L9: 4 | M9: 1 | N9: 35 | O9: 10 | P9: 91
B10: Lease Liabilities | C10: 261 | D10: 244 | E10: 267 | F10: 292 | G10: 193
C11: 0 | D11: 0 | E11: 0 | F11: 0 | G11: 0 | K11: Proceeds from borrowings | L11: 0 | M11: 0 | N11: 0 | O11: 8 | P11: 90
B12: Other Liabilities | K12: Repayment of borrowings | L12: -2 | M12: -1 | N12: -1 | O12: -2 | P12: -54
B13: Non controlling int | C13: 347 | D13: 366 | E13: 384 | F13: 383 | G13: 368 | K13: Interest paid fin | L13: -41 | M13: -40 | N13: -41 | O13: -46 | P13: -50
B14: Trade Payables | C14: 4319 | D14: 4417 | E14: 4659 | F14: 4798 | G14: 4807
B15: Advance from Customers | C15: 811 | D15: 1278 | E15: 1295 | F15: 886 | G15: 1264
B16: Other liability items | C16: 7666 | D16: 8429 | E16: 10032 | F16: 10877 | G16: 11249
B17: Total Liabilities | C17: 73761 | D17: 77196 | E17: 85831 | F17: 91754 | G17: 88003
B19: Fixed Assets | I19: Working Capital Schedule | J19: 43891 | K19: =L7 -> 44256 | L19: =M7 -> 44621 | M19: =N7 -> 44986 | N19: =O7 -> 45352 | O19: =P7 -> 45717
B20: Land | C20: 2889 | D20: 2829 | E20: 2830 | F20: 2865 | G20: 1588 | I20: Debtors | J20: ='Historical FS'!G65 -> 2562.48 | K20: ='Historical FS'!H65 -> 2501.7 | L20: ='Historical FS'!I65 -> 2461.9 | M20: ='Historical FS'!J65 -> 2956.17 | N20: ='Historical FS'!K65 -> 4025.82 | O20: ='Historical FS'!L65 -> 4719.67
B21: Building | C21: 8387 | D21: 9100 | E21: 9789 | F21: 10944 | G21: 7550 | I21: Inventory | J21: ='Historical FS'!G66 -> 8879.33 | K21: ='Historical FS'!H66 -> 10397.16 | L21: ='Historical FS'!I66 -> 10864.15 | M21: ='Historical FS'!J66 -> 11771.16 | N21: ='Historical FS'!K66 -> 14152.88 | O21: ='Historical FS'!L66 -> 15637.56
B22: Plant Machinery | C22: 15307 | D22: 16912 | E22: 18480 | F22: 20718 | G22: 19423 | I22: CA | J22: =SUM(J20:J21) -> 11441.81 | K22: =SUM(K20:K21) -> 12898.86 | L22: =SUM(L20:L21) -> 13326.05 | M22: =SUM(M20:M21) -> 14727.33 | N22: =SUM(N20:N21) -> 18178.7 | O22: =SUM(O20:O21) -> 20357.23
B23: Equipments | C23: 41 | D23: 44 | E23: 44 | F23: 53 | G23: 63 | I23: Change in CA | K23: =K22-J22 -> 1457.05 | L23: =L22-K22 -> 427.19 | M23: =M22-L22 -> 1401.28 | N23: =N22-M22 -> 3451.37 | O23: =O22-N22 -> 2178.53
B24: Furniture n fittings | C24: 833 | D24: 907 | E24: 1000 | F24: 1068 | G24: 282 | I24: Payables | J24: 3630 | K24: ='Expanded BS'!C14 -> 4319 | L24: ='Expanded BS'!D14 -> 4417 | M24: ='Expanded BS'!E14 -> 4659 | N24: ='Expanded BS'!F14 -> 4798 | O24: ='Expanded BS'!G14 -> 4807
B25: Railway sidings | C25: 2 | D25: 2 | E25: 2 | F25: 2 | G25: 2 | I25: Advance from Customer | J25: 703 | K25: =C15 -> 811 | L25: =D15 -> 1278 | M25: =E15 -> 1295 | N25: =F15 -> 886 | O25: =G15 -> 1264
B26: Vehicles | C26: 180 | D26: 179 | E26: 189 | F26: 192 | G26: 141 | I26: Other liability items | J26: 7050 | K26: =C16 -> 7666 | L26: =D16 -> 8429 | M26: =E16 -> 10032 | N26: =F16 -> 10877 | O26: =G16 -> 11249
B27: Intangible Assets | C27: 2734 | D27: 2744 | E27: 3490 | F27: 3505 | G27: 3622 | I27: CL | J27: =SUM(J24:J26) -> 11383 | K27: =SUM(K24:K26) -> 12796 | L27: =SUM(L24:L26) -> 14124 | M27: =SUM(M24:M26) -> 15986 | N27: =SUM(N24:N26) -> 16561 | O27: =SUM(O24:O26) -> 17320
B28: Other fixed assets | C28: 716 | D28: 719 | E28: 786 | F28: 841 | G28: 967 | I28: Change in CL | K28: =K27-J27 -> 1413 | L28: =L27-K27 -> 1328 | M28: =M27-L27 -> 1862 | N28: =N27-M27 -> 575 | O28: =O27-N27 -> 759
B29: Gross Block | C29: 31088 | D29: 33435 | E29: 36608 | F29: 40189 | G29: 33638
B30: Accumulated Depreciation | C30: 7790 | D30: 9204 | E30: 10757 | F30: 12368 | G30: 11683 | I30: NWC | J30: =J22-J27 -> 58.81 | K30: =K22-K27 -> 102.86 | L30: =L22-L27 -> -797.95 | M30: =M22-M27 -> -1258.67 | N30: =N22-N27 -> 1617.7 | O30: =O22-O27 -> 3037.23
B31: Net Block | C31: =C29-C30 -> 23298 | D31: =D29-D30 -> 24231 | E31: =E29-E30 -> 25851 | F31: =F29-F30 -> 27821 | G31: =G29-G30 -> 21955
I32: Change | K32: =K30-J30 -> 44.05 | L32: =L30-K30 -> -900.81 | M32: =M30-L30 -> -460.72 | N32: =N30-M30 -> 2876.37 | O32: =O30-N30 -> 1419.53
B33: CWIP | C33: 4011 | D33: 3226 | E33: 3003 | F33: 2861 | G33: 1091
B34: Investments | C34: 24871 | D34: 24841 | E34: 29415 | F34: 31114 | G34: 34720
B36: Other Assets
B37: Inventories | C37: 10397 | D37: 10864 | E37: 11771 | F37: 14153 | G37: 15638
B38: Trade receivables | C38: 2502 | D38: 2462 | E38: 2956 | F38: 4026 | G38: 4720
B39: Cash Equivalents | C39: 4659 | D39: 4654 | E39: 4880 | F39: 7218 | G39: 4012
B40: Loans n Advances | C40: 7 | D40: 11 | E40: 13 | F40: 31 | G40: 10
B41: Other asset items | C41: 4015 | D41: 6906 | E41: 7941 | F41: 4531 | G41: 5858
B42: Total Assets | C42: 73761 | D42: 77196 | E42: 85831 | F42: 91754 | G42: 88003

Sheet Cash Flow Statement
B2: Cash Flow Statement
C3: 44256 | D3: 44621 | E3: 44986 | F3: 45352 | G3: 45717
B4: Cash from Operating Activity | C4: =SUM(C5:C10) -> 12112 | D4: =SUM(D5:D10) -> 15676 | E4: =SUM(E5:E10) -> 17954 | F4: =SUM(F5:F10) -> 13840 | G4: =SUM(G5:G10) -> 14885
B5: Profit from operations | C5: 17326 | D5: 20857 | E5: 26052 | F5: 26635 | G5: 26719
B6: Receivables | C6: -66 | D6: -732 | E6: -884 | F6: -934 | G6: -1023
B7: Inventory | C7: -1460 | D7: -466 | E7: -1098 | F7: -2545 | G7: -2975
B8: Payables | C8: 1112 | D8: 1099 | E8: 1058 | F8: 141 | G8: 1256
B9: Working capital changes | C9: -413 | D9: -100 | E9: -924 | F9: -3337 | G9: -2742
B10: Direct taxes | C10: -4387 | D10: -4982 | E10: -6250 | F10: -6120 | G10: -6350
B11: Cash from Investing Activity | C11: =SUM(C12:C21) -> 5741 | D11: =SUM(D12:D21) -> -2238 | E11: =SUM(E12:E21) -> -5732 | F11: =SUM(F12:F21) -> 1563 | G11: =SUM(G12:G21) -> -564
B12: Fixed assets purchased | C12: -1837 | D12: -2142 | E12: -2743 | F12: -3563 | G12: -2279
B13: Fixed assets sold | C13: 3 | D13: 133 | E13: 49 | F13: 107 | G13: 175
B14: Investments purchased | C14: -57553 | D14: -69776 | E14: -80932 | F14: -75107 | G14: -66373
B15: Investments sold | C15: 62797 | D15: 70992 | E15: 77230 | F15: 77830 | G15: 67311
B16: Interest received | C16: 1275 | D16: 1035 | E16: 1324 | F16: 1138 | G16: 1072
B17: Dividends received | C17: 7 | D17: 16 | E17: 19 | F17: 36 | G17: 38
B18: Invest in subsidiaries | C18: 0 | D18: 0 | E18: 0 | F18: 0 | G18: 0
B19: Investment in group cos | C19: -2 | D19: -2 | E19: -2 | F19: -65 | G19: -30
B20: Redemp n Canc of Shares | C20: 0 | D20: 0 | E20: 56 | F20: 0 | G20: 0
B21: Other investing items | C21: 1051 | D21: -2494 | E21: -733 | F21: 1187 | G21: -478
B22: Cash from Financing Activity | C22: =SUM(C23:C29) -> -18633 | D22: =SUM(D23:D29) -> -13581 | E22: =SUM(E23:E29) -> -13007 | F22: =SUM(F23:F29) -> -18551 | G22: =SUM(G23:G29) -> -16985
B23: Proceeds from shares | C23: 291 | D23: 292 | E23: 2477 | F23: 1443 | G23: 797
B24: Proceeds from borrowings | C24: 0 | D24: 0 | E24: 0 | F24: 8 | G24: 90
B25: Repayment of borrowings | C25: -2 | D25: -1 | E25: -1 | F25: -2 | G25: -2
B26: Interest paid fin | C26: -41 | D26: -40 | E26: -41 | F26: -46 | G26: -50
B27: Dividends paid | C27: -18881 | D27: -13788 | E27: -15418 | F27: -19899 | G27: -17782
B28: Financial liabilities | C28: -55 | D28: -59 | E28: -59 | F28: -67 | G28: -66
B29: Other financing items | C29: 55 | D29: 15 | E29: 35 | F29: 12 | G29: 28
B30: Net Cash Flow | C30: =C4+C11+C22 -> -780 | D30: =D4+D11+D22 -> -143 | E30: =E4+E11+E22 -> -785 | F30: =F4+F11+F22 -> -3148 | G30: =G4+G11+G22 -> -2664

Sheet Profit & Loss
A1: ='[1]Data Sheet'!B1 -> ITC LTD | H1: =UPDATE | M1: SCREENER.IN
A3: Narration | B3: ='[1]Data Sheet'!B16 -> 42460 | C3: ='[1]Data Sheet'!C16 -> 42825 | D3: ='[1]Data Sheet'!D16 -> 43190 | E3: ='[1]Data Sheet'!E16 -> 43555 | F3: ='[1]Data Sheet'!F16 -> 43921 | G3: ='[1]Data Sheet'!G16 -> 44286 | H3: ='[1]Data Sheet'!H16 -> 44651 | I3: ='[1]Data Sheet'!I16 -> 45016 | ... K3: ='[1]Data Sheet'!K16 -> 45747 | L3: Trailing | M3: Best Case | N3: Worst Case
A4: Sales | B4: ='[1]Data Sheet'!B17 -> 39192.1 | C4: ='[1]Data Sheet'!C17 -> 42767.6 | D4: ='[1]Data Sheet'!D17 -> 43448.94 | E4: ='[1]Data Sheet'!E17 -> 48339.58 | F4: ='[1]Data Sheet'!F17 -> 49387.7 | G4: ='[1]Data Sheet'!G17 -> 49257.45 | H4: ='[1]Data Sheet'!H17 -> 60644.54 | I4: ='[1]Data Sheet'!I17 -> 70919.03 | ... K4: ='[1]Data Sheet'!K17 -> 75323.34 | L4: =SUM([1]Quarters!H4:K4) -> 79040.32 | M4: =$K4+M23*K4 -> 83518.968 | N4: =$K4+N23*L4 -> 81245.656
A5: Expenses | B5: =SUM('[1]Data Sheet'!B18,'[1]Data Sheet'!B20:B24, -1*'[1]Data Sheet'!B19) -> 24660.61 | C5: =SUM('[1]Data Sheet'!C18,'[1]Data Sheet'!C20:C24, -1*'[1]Data Sheet'!C19) -> 27298.09 | D5: =SUM('[1]Data Sheet'!D18,'[1]Data Sheet'!D20:D24, -1*'[1]Data Sheet'!D19) -> 26928.35 | E5: =SUM('[1]Data Sheet'!E18,'[1]Data Sheet'!E20:E24, -1*'[1]Data Sheet'!E19) -> 29802.19 | F5: =SUM('[1]Data Sheet'!F18,'[1]Data Sheet'!F20:F24, -1*'[1]Data Sheet'!F19) -> 30044.16 | G5: =SUM('[1]Data Sheet'!G18,'[1]Data Sheet'!G20:G24, -1*'[1]Data Sheet'!G19) -> 32192.67 | H5: =SUM('[1]Data Sheet'!H18,'[1]Data Sheet'!H20:H24, -1*'[1]Data Sheet'!H19) -> 40021.39 | I5: =SUM('[1]Data Sheet'!I18,'[1]Data Sheet'!I20:I24, -1*'[1]Data Sheet'!I19) -> 45214.77 | ... K5: =SUM('[1]Data Sheet'!K18,'[1]Data Sheet'!K20:K24, -1*'[1]Data Sheet'!K19) -> 49483.89 | L5: =SUM([1]Quarters!H5:K5) -> 52790.48 | M5: =M4-M6 -> 53597.014 | N5: =N4-N6 -> 54263.409
A6: Operating Profit | B6: =B4-B5 -> 14531.49 | C6: =C4-C5 -> 15469.51 | D6: =D4-D5 -> 16520.59 | E6: =E4-E5 -> 18537.39 | F6: =F4-F5 -> 19343.54 | G6: =G4-G5 -> 17064.78 | H6: =H4-H5 -> 20623.15 | I6: =I4-I5 -> 25704.26 | ... K6: =K4-K5 -> 25839.45 | L6: =SUM([1]Quarters!H6:K6) -> 26249.84 | M6: =M4*M24 -> 29921.955 | N6: =N4*N24 -> 26982.247
A7: Other Income | B7: ='[1]Data Sheet'!B25 -> 1483.11 | C7: ='[1]Data Sheet'!C25 -> 1758.63 | D7: ='[1]Data Sheet'!D25 -> 2239.81 | E7: ='[1]Data Sheet'!E25 -> 2080.44 | F7: ='[1]Data Sheet'!F25 -> 2417.32 | G7: ='[1]Data Sheet'!G25 -> 2576.95 | H7: ='[1]Data Sheet'!H25 -> 1909.72 | I7: ='[1]Data Sheet'!I25 -> 2097.64 | ... K7: ='[1]Data Sheet'!K25 -> 17794.88 | L7: =SUM([1]Quarters!H7:K7) -> 17635.96 | M7: 0 | N7: 0
A8: Depreciation | B8: ='[1]Data Sheet'!B26 -> 1077.4 | C8: ='[1]Data Sheet'!C26 -> 1152.79 | D8: ='[1]Data Sheet'!D26 -> 1236.28 | E8: ='[1]Data Sheet'!E26 -> 1396.61 | F8: ='[1]Data Sheet'!F26 -> 1644.91 | G8: ='[1]Data Sheet'!G26 -> 1645.59 | H8: ='[1]Data Sheet'!H26 -> 1732.41 | I8: ='[1]Data Sheet'!I26 -> 1809.01 | ... K8: ='[1]Data Sheet'!K26 -> 1646.32 | L8: =SUM([1]Quarters!H8:K8) -> 1666.15 | M8: =+$L8 -> 1666.15 | N8: =+$L8 -> 1666.15
A9: Interest | B9: ='[1]Data Sheet'!B27 -> 78.13 | C9: ='[1]Data Sheet'!C27 -> 49.03 | D9: ='[1]Data Sheet'!D27 -> 115.01 | E9: ='[1]Data Sheet'!E27 -> 71.4 | F9: ='[1]Data Sheet'!F27 -> 81.38 | G9: ='[1]Data Sheet'!G27 -> 57.97 | H9: ='[1]Data Sheet'!H27 -> 59.99 | I9: ='[1]Data Sheet'!I27 -> 77.77 | ... K9: ='[1]Data Sheet'!K27 -> 45.06 | L9: =SUM([1]Quarters!H9:K9) -> 51.93 | M9: =+$L9 -> 51.93 | N9: =+$L9 -> 51.93
A10: Profit before tax | B10: ='[1]Data Sheet'!B28 -> 14859.07 | C10: ='[1]Data Sheet'!C28 -> 16026.32 | D10: ='[1]Data Sheet'!D28 -> 17409.11 | E10: ='[1]Data Sheet'!E28 -> 19149.82 | F10: ='[1]Data Sheet'!F28 -> 20034.57 | G10: ='[1]Data Sheet'!G28 -> 17938.17 | H10: ='[1]Data Sheet'!H28 -> 20740.47 | I10: ='[1]Data Sheet'!I28 -> 25915.12 | ... K10: ='[1]Data Sheet'!K28 -> 41942.95 | L10: =SUM([1]Quarters!H10:K10) -> 42167.72 | M10: =M6+M7-SUM(M8:M9) -> 28203.875 | N10: =N6+N7-SUM(N8:N9) -> 25264.167
A11: Tax | B11: ='[1]Data Sheet'!B29 -> 5358.21 | C11: ='[1]Data Sheet'!C29 -> 5549.09 | D11: ='[1]Data Sheet'!D29 -> 5916.43 | E11: ='[1]Data Sheet'!E29 -> 6313.92 | F11: ='[1]Data Sheet'!F29 -> 4441.79 | G11: ='[1]Data Sheet'!G29 -> 4555.29 | H11: ='[1]Data Sheet'!H29 -> 5237.34 | I11: ='[1]Data Sheet'!I29 -> 6438.4 | ... K11: ='[1]Data Sheet'!K29 -> 6890.47 | L11: =SUM([1]Quarters!H11:K11) -> 6948.82 | M11: =IF($L10>0,$L11/$L10,0) -> 0.16479003 | N11: =IF($L10>0,$L11/$L10,0) -> 0.16479003
A12: Net profit | B12: ='[1]Data Sheet'!B30 -> 9344.45 | C12: ='[1]Data Sheet'!C30 -> 10289.44 | D12: ='[1]Data Sheet'!D30 -> 11271.2 | E12: ='[1]Data Sheet'!E30 -> 12592.33 | F12: ='[1]Data Sheet'!F30 -> 15306.23 | G12: ='[1]Data Sheet'!G30 -> 13161.19 | H12: ='[1]Data Sheet'!H30 -> 15242.66 | I12: ='[1]Data Sheet'!I30 -> 19191.66 | ... K12: ='[1]Data Sheet'!K30 -> 34746.63 | L12: =SUM([1]Quarters!H12:K12) -> 34899.24 | M12: =M10-M11*M10 -> 23556.157 | N12: =N10-N11*N10 -> 21100.884
A13: EPS | B13: =IF('[1]Data Sheet'!B93>0,B12/'[1]Data Sheet'!B93,0) -> 7.7413676 | C13: =IF('[1]Data Sheet'!C93>0,C12/'[1]Data Sheet'!C93,0) -> 8.4704875 | D13: =IF('[1]Data Sheet'!D93>0,D12/'[1]Data Sheet'!D93,0) -> 9.2354334 | E13: =IF('[1]Data Sheet'!E93>0,E12/'[1]Data Sheet'!E93,0) -> 10.272242 | F13: =IF('[1]Data Sheet'!F93>0,F12/'[1]Data Sheet'!F93,0) -> 12.451986 | G13: =IF('[1]Data Sheet'!G93>0,G12/'[1]Data Sheet'!G93,0) -> 10.692505 | H13: =IF('[1]Data Sheet'!H93>0,H12/'[1]Data Sheet'!H93,0) -> 12.368976 | I13: =IF('[1]Data Sheet'!I93>0,I12/'[1]Data Sheet'!I93,0) -> 15.442276 | ... K13: =IF('[1]Data Sheet'!K93>0,K12/'[1]Data Sheet'!K93,0) -> 27.765984 | L13: =IF('[1]Data Sheet'!$B6>0,'Profit & Loss'!L12/'[1]Data Sheet'!$B6,0) -> 27.87033 | M13: =IF('[1]Data Sheet'!$B6>0,'Profit & Loss'!M12/'[1]Data Sheet'!$B6,0) -> 18.81181 | N13: =IF('[1]Data Sheet'!$B6>0,'Profit & Loss'!N12/'[1]Data Sheet'!$B6,0) -> 16.851044
A14: Price to earning | B14: =IF(B15>0,B15/B13,"") -> 26.497902 | C14: =IF(C15>0,C15/C13,"") -> 31.019466 | D14: =IF(D15>0,D15/D13,"") -> 25.93273 | E14: =IF(E15>0,E15/E13,"") -> 27.12553 | F14: =IF(F15>0,F15/F13,"") -> 12.925649 | G14: =IF(G15>0,G15/G13,"") -> 19.155475 | H14: =IF(H15>0,H15/H13,"") -> 18.995914 | I14: =IF(I15>0,I15/I13,"") -> 23.2796 | ... K14: =IF(K15>0,K15/K13,"") -> 14.757266 | L14: =IF(L13>0,L15/L13,0) -> 14.388061 | M14: =M25 -> 19.231941 | N14: =N25 -> 14.388061
A15: Price | B15: ='[1]Data Sheet'!B90 -> 205.13 | C15: ='[1]Data Sheet'!C90 -> 262.75 | D15: ='[1]Data Sheet'!D90 -> 239.5 | E15: ='[1]Data Sheet'!E90 -> 278.64 | F15: ='[1]Data Sheet'!F90 -> 160.95 | G15: ='[1]Data Sheet'!G90 -> 204.82 | H15: ='[1]Data Sheet'!H90 -> 234.96 | I15: ='[1]Data Sheet'!I90 -> 359.49 | ... K15: ='[1]Data Sheet'!K90 -> 409.75 | L15: ='[1]Data Sheet'!B8 -> 401 | M15: =M13*M14 -> 361.78762 | N15: =N13*N14 -> 242.45384
A17: RATIOS:
A18: Dividend Payout | B18: =IF('[1]Data Sheet'!B30>0, '[1]Data Sheet'!B31/'[1]Data Sheet'!B30, 0) -> 0.73199814 | C18: =IF('[1]Data Sheet'!C30>0, '[1]Data Sheet'!C31/'[1]Data Sheet'!C30, 0) -> 0.56077104 | D18: =IF('[1]Data Sheet'!D30>0, '[1]Data Sheet'!D31/'[1]Data Sheet'!D30, 0) -> 0.5576345 | E18: =IF('[1]Data Sheet'!E30>0, '[1]Data Sheet'!E31/'[1]Data Sheet'!E30, 0) -> 0.55976138 | F18: =IF('[1]Data Sheet'!F30>0, '[1]Data Sheet'!F31/'[1]Data Sheet'!F30, 0) -> 0.81513083 | G18: =IF('[1]Data Sheet'!G30>0, '[1]Data Sheet'!G31/'[1]Data Sheet'!G30, 0) -> 1.0053772 | H18: =IF('[1]Data Sheet'!H30>0, '[1]Data Sheet'!H31/'[1]Data Sheet'!H30, 0) -> 0.92974586 | I18: =IF('[1]Data Sheet'!I30>0, '[1]Data Sheet'!I31/'[1]Data Sheet'!I30, 0) -> 1.0037381 | ... K18: =IF('[1]Data Sheet'!K30>0, '[1]Data Sheet'!K31/'[1]Data Sheet'!K30, 0) -> 0.51681933
A19: OPM | B19: =IF(B6>0,B6/B4,0) -> 0.370776 | C19: =IF(C6>0,C6/C4,0) -> 0.36171097 | D19: =IF(D6>0,D6/D4,0) -> 0.38022999 | E19: =IF(E6>0,E6/E4,0) -> 0.38348265 | F19: =IF(F6>0,F6/F4,0) -> 0.39166716 | G19: =IF(G6>0,G6/G4,0) -> 0.34644059 | H19: =IF(H6>0,H6/H4,0) -> 0.34006606 | I19: =IF(I6>0,I6/I4,0) -> 0.36244517 | ... L19: =IF(L6>0,L6/L4,0) -> 0.33210696
G22: TRENDS: | H22: 10 YEARS | I22: 7 YEARS | J22: 5 YEARS | K22: 3 YEARS | L22: RECENT | M22: BEST | N22: WORST
G23: Sales Growth | H23: =IF(B4=0,"",POWER($K4/B4,1/9)-1) -> 0.075290157 | I23: =IF(D4=0,"",POWER($K4/D4,1/7)-1) -> 0.081772082 | J23: =IF(F4=0,"",POWER($K4/F4,1/5)-1) -> 0.088083322 | K23: =IF(H4=0,"",POWER($K4/H4, 1/3)-1) -> 0.074927782 | L23: =IF(ISERROR(MAX(IF(J4=0,"",(K4-J4)/J4),IF(K4=0,"",(L4-K4)/K4))),"",MAX(IF(J4=0,"",(K4-J4)/J4),IF(K4=0,"",(L4-K4)/K4))) -> 0.10880596 | M23: =MAX(K23:L23) -> 0.10880596 | N23: =MIN(H23:L23) -> 0.074927782
G24: OPM | H24: =IF(SUM(B4:$K$4)=0,"",SUMPRODUCT(B19:$K$19,B4:$K$4)/SUM(B4:$K$4)) -> 0.36333562 | I24: =IF(SUM(E4:$K$4)=0,"",SUMPRODUCT(E19:$K$19,E4:$K$4)/SUM(E4:$K$4)) -> 0.36106877 | J24: =IF(SUM(G4:$K$4)=0,"",SUMPRODUCT(G19:$K$19,G4:$K$4)/SUM(G4:$K$4)) -> 0.35306244 | K24: =IF(SUM(I4:$K$4)=0, "", SUMPRODUCT(I19:$K$19,I4:$K$4)/SUM(I4:$K$4)) -> 0.35826538 | L24: =L19 -> 0.33210696 | M24: =MAX(K24:L24) -> 0.35826538 | N24: =MIN(H24:L24) -> 0.33210696
G25: Price to Earning | H25: =IF(ISERROR(AVERAGEIF(B14:$L14,">0")),"",AVERAGEIF(B14:$L14,">0")) -> 21.68913 | I25: =IF(ISERROR(AVERAGEIF(E14:$L14,">0")),"",AVERAGEIF(E14:$L14,">0")) -> 19.391291 | J25: =IF(ISERROR(AVERAGEIF(G14:$L14,">0")),"",AVERAGEIF(G14:$L14,">0")) -> 19.179859 | K25: =IF(ISERROR(AVERAGEIF(I14:$L14,">0")),"",AVERAGEIF(I14:$L14,">0")) -> 19.231941 | L25: =L14 -> 14.388061 | M25: =MAX(K25:L25) -> 19.231941 | N25: =MIN(H25:L25) -> 14.388061
A27: Sales Growth YoY | C27: =C4/B4-1 -> 0.09123012 | D27: =D4/C4-1 -> 0.015931219 | E27: =E4/D4-1 -> 0.11256063 | F27: =F4/E4-1 -> 0.021682439 | G27: =G4/F4-1 -> -0.0026372963 | H27: =H4/G4-1 -> 0.23117498 | I27: =I4/H4-1 -> 0.16942152 | J27: =J4/I4-1 -> -0.042119724 | K27: =K4/J4-1 -> 0.10880596
A28: Gross Profit | B28: ='[1]Data Sheet'!B17-'[1]Data Sheet'!B18-'[1]Data Sheet'!B19-'[1]Data Sheet'!B20-'[1]Data Sheet'!B21 -> 23079.37 | C28: ='[1]Data Sheet'!C17-'[1]Data Sheet'!C18-'[1]Data Sheet'!C19-'[1]Data Sheet'!C20-'[1]Data Sheet'!C21 -> 25635.35 | D28: ='[1]Data Sheet'!D17-'[1]Data Sheet'!D18-'[1]Data Sheet'!D19-'[1]Data Sheet'!D20-'[1]Data Sheet'!D21 -> 27297.86 | E28: ='[1]Data Sheet'!E17-'[1]Data Sheet'!E18-'[1]Data Sheet'!E19-'[1]Data Sheet'!E20-'[1]Data Sheet'!E21 -> 27895.13 | F28: ='[1]Data Sheet'!F17-'[1]Data Sheet'!F18-'[1]Data Sheet'!F19-'[1]Data Sheet'!F20-'[1]Data Sheet'!F21 -> 27946.83 | G28: ='[1]Data Sheet'!G17-'[1]Data Sheet'!G18-'[1]Data Sheet'!G19-'[1]Data Sheet'!G20-'[1]Data Sheet'!G21 -> 25548.73 | H28: ='[1]Data Sheet'!H17-'[1]Data Sheet'!H18-'[1]Data Sheet'!H19-'[1]Data Sheet'!H20-'[1]Data Sheet'!H21 -> 30110.03 | I28: ='[1]Data Sheet'!I17-'[1]Data Sheet'!I18-'[1]Data Sheet'!I19-'[1]Data Sheet'!I20-'[1]Data Sheet'!I21 -> 37635.94 | ... K28: ='[1]Data Sheet'!K17-'[1]Data Sheet'!K18-'[1]Data Sheet'!K19-'[1]Data Sheet'!K20-'[1]Data Sheet'!K21 -> 38572.61
A29: Gross Profit Margins % | C29: =C28/B28-1 -> 0.11074739 | D29: =D28/C28-1 -> 0.064852245 | E29: =E28/D28-1 -> 0.021879737 | F29: =F28/E28-1 -> 0.0018533701 | G29: =G28/F28-1 -> -0.085809374 | H29: =H28/G28-1 -> 0.17853334 | I29: =I28/H28-1 -> 0.24994694 | J29: =J28/I28-1 -> -0.014799683 | K29: =K28/J28-1 -> 0.040283514
A30: EBITDA Margins % | B30: =B6/B4 -> 0.370776 | C30: =C6/C4 -> 0.36171097 | D30: =D6/D4 -> 0.38022999 | E30: =E6/E4 -> 0.38348265 | F30: =F6/F4 -> 0.39166716 | G30: =G6/G4 -> 0.34644059 | H30: =H6/H4 -> 0.34006606 | I30: =I6/I4 -> 0.36244517 | ... K30: =K6/K4 -> 0.34304706
A31: EBIT Margins % | B31: =(B6-B8)/B4 -> 0.34328576 | C31: =(C6-C8)/C4 -> 0.33475622 | D31: =(D6-D8)/D4 -> 0.35177636 | E31: =(E6-E8)/E4 -> 0.354591 | F31: =(F6-F8)/F4 -> 0.35836109 | G31: =(G6-G8)/G4 -> 0.31303265 | H31: =(H6-H8)/H4 -> 0.31149944 | I31: =(I6-I8)/I4 -> 0.33693707 | ... K31: =(K6-K8)/K4 -> 0.32119035
A32: Net Profit Margins % | B32: =B12/B4 -> 0.23842688 | C32: =C12/C4 -> 0.24058961 | D32: =D12/D4 -> 0.25941254 | E32: =E12/E4 -> 0.2604973 | F32: =F12/F4 -> 0.30991988 | G32: =G12/G4 -> 0.26719187 | H32: =H12/H4 -> 0.25134431 | I32: =I12/I4 -> 0.27061368 | ... K32: =K12/K4 -> 0.46129964
A33: Earnings Per Share | B33: =B13 -> 7.7413676 | C33: =C13 -> 8.4704875 | D33: =D13 -> 9.2354334 | E33: =E13 -> 10.272242 | F33: =F13 -> 12.451986 | G33: =G13 -> 10.692505 | H33: =H13 -> 12.368976 | I33: =I13 -> 15.442276 | ... K33: =K13 -> 27.765984
A34: EPS Growth YoY | C34: =C13/B13-1 -> 0.094184898 | D34: =D13/C13-1 -> 0.090307187 | E34: =E13/D13-1 -> 0.11226415 | F34: =F13/E13-1 -> 0.21219753 | G34: =G13/F13-1 -> -0.14130126 | H34: =H13/G13-1 -> 0.15678939 | I34: =I13/H13-1 -> 0.2484684 | J34: =J13/I13-1 -> 0.0611831 | K34: =K13/J13-1 -> 0.69438246
A35: Dividend Per Share | B35: =B18*B13 -> 5.6666667 | C35: =C18*C13 -> 4.7500041 | D35: =D18*D13 -> 5.1499963 | E35: =E18*E13 -> 5.7500041 | F35: =F18*F13 -> 10.149998 | G35: =G18*G13 -> 10.75 | H35: =H18*H13 -> 11.500004 | I35: =I18*I13 -> 15.5 | ... K35: =K18*K13 -> 14.349997
A36: DPS Growth YoY | C36: =C35/B35-1 -> -0.16176398 | D36: =D35/C35-1 -> 0.084208811 | E36: =E35/D35-1 -> 0.11650645 | F36: =F35/E35-1 -> 0.76521571 | G36: =G35/F35-1 -> 0.059113555 | H36: =H35/G35-1 -> 0.069767819 | I36: =I35/H35-1 -> 0.34782561 | J36: =J35/I35-1 -> -0.11290335 | K36: =K35/J35-1 -> 0.043636312
A38: COGS % Revenue | B38: =1-(B28/B4) -> 0.41112188 | C38: =1-(C28/C4) -> 0.40058946 | D38: =1-(D28/D4) -> 0.37172552 | E38: =1-(E28/E4) -> 0.42293396 | F38: =1-(F28/F4) -> 0.4341338 | G38: =1-(G28/G4) -> 0.48132252 | H38: =1-(H28/H4) -> 0.50349974 | I38: =1-(I28/I4) -> 0.46931113 | ... K38: =1-(K28/K4) -> 0.48790627
A39: Employees Cost % Rev | B39: =SUM('Data Sheet'!B22:B23)/'Data Sheet'!B17 -> 0.19653833 | C39: =SUM('Data Sheet'!C22:C23)/'Data Sheet'!C17 -> 0.18264925 | D39: =SUM('Data Sheet'!D22:D23)/'Data Sheet'!D17 -> 0.17758247 | E39: =SUM('Data Sheet'!E22:E23)/'Data Sheet'!E17 -> 0.18047881 | F39: =SUM('Data Sheet'!F22:F23)/'Data Sheet'!F17 -> 0.17786655 | G39: =SUM('Data Sheet'!G22:G23)/'Data Sheet'!G17 -> 0.17662506 | H39: =SUM('Data Sheet'!H22:H23)/'Data Sheet'!H17 -> 0.16075528 | I39: =SUM('Data Sheet'!I22:I23)/'Data Sheet'!I17 -> 0.15990489 | ... K39: =SUM('Data Sheet'!K22:K23)/'Data Sheet'!K17 -> 0.15882288
A40: YoY Other Expense Growth % | C40: ='Data Sheet'!C24/'Data Sheet'!B24-1 -> -0.053936839 | D40: ='Data Sheet'!D24/'Data Sheet'!C24-1 -> -0.1396218 | E40: ='Data Sheet'!E24/'Data Sheet'!D24-1 -> 0.033668661 | F40: ='Data Sheet'!F24/'Data Sheet'!E24-1 -> 0.17817955 | G40: ='Data Sheet'!G24/'Data Sheet'!F24-1 -> -0.12304 | H40: ='Data Sheet'!H24/'Data Sheet'!G24-1 -> 0.033097851 | I40: ='Data Sheet'!I24/'Data Sheet'!H24-1 -> 0.17893599 | J40: ='Data Sheet'!J24/'Data Sheet'!I24-1 -> 0.34955218 | K40: ='Data Sheet'!K24/'Data Sheet'!J24-1 -> 0.2578866
A41: Yoy Other Income Growth % | C41: ='Historical FS'!D20/'Historical FS'!C20-1 -> 0.18577179 | D41: ='Historical FS'!E20/'Historical FS'!D20-1 -> 0.27361071 | E41: ='Historical FS'!F20/'Historical FS'!E20-1 -> -0.071153357 | F41: ='Historical FS'!G20/'Historical FS'!F20-1 -> 0.16192728 | G41: ='Historical FS'!H20/'Historical FS'!G20-1 -> 0.066035941 | H41: ='Historical FS'!I20/'Historical FS'!H20-1 -> -0.25892237 | I41: ='Historical FS'!J20/'Historical FS'!I20-1 -> 0.09840186 | J41: ='Historical FS'!K20/'Historical FS'!J20-1 -> 0.58771286 | K41: ='Historical FS'!L20/'Historical FS'!K20-1 -> 0.037097089
B42: 100 | C42: =B42*(1+C41) -> 118.57718 | D42: =C42*(1+D41) -> 151.02116 | E42: =D42*(1+E41) -> 140.2755 | F42: =E42*(1+F41) -> 162.98993 | G42: =F42*(1+G41) -> 173.75313 | H42: =G42*(1+H41) -> 128.76456 | I42: =H42*(1+I41) -> 141.43523 | J42: =I42*(1+J41) -> 224.55853 | K42: =J42*(1+K41) -> 232.889
K43: =_xlfn.RRI(4,G42,K42) -> 0.075979719

Sheet Balance Sheet
A1: ='[1]Profit & Loss'!A1 -> ITC LTD | E1: =UPDATE | J1: SCREENER.IN
A3: Narration | B3: ='[1]Data Sheet'!B56 -> 42460 | C3: ='[1]Data Sheet'!C56 -> 42825 | D3: ='[1]Data Sheet'!D56 -> 43190 | E3: ='[1]Data Sheet'!E56 -> 43555 | F3: ='[1]Data Sheet'!F56 -> 43921 | G3: ='[1]Data Sheet'!G56 -> 44286 | H3: ='[1]Data Sheet'!H56 -> 44651 | I3: ='[1]Data Sheet'!I56 -> 45016 | ... K3: ='[1]Data Sheet'!K56 -> 45747
A4: Equity Share Capital | B4: ='[1]Data Sheet'!B57 -> 804.72 | C4: ='[1]Data Sheet'!C57 -> 1214.74 | D4: ='[1]Data Sheet'!D57 -> 1220.43 | E4: ='[1]Data Sheet'!E57 -> 1225.86 | F4: ='[1]Data Sheet'!F57 -> 1229.22 | G4: ='[1]Data Sheet'!G57 -> 1230.88 | H4: ='[1]Data Sheet'!H57 -> 1232.33 | I4: ='[1]Data Sheet'!I57 -> 1242.8 | ... K4: ='[1]Data Sheet'!K57 -> 1251.41
A5: Reserves | B5: ='[1]Data Sheet'!B58 -> 41874.8 | C5: ='[1]Data Sheet'!C58 -> 45198.19 | D5: ='[1]Data Sheet'!D58 -> 51289.68 | E5: ='[1]Data Sheet'!E58 -> 57915.01 | F5: ='[1]Data Sheet'!F58 -> 64044.04 | G5: ='[1]Data Sheet'!G58 -> 59116.46 | H5: ='[1]Data Sheet'!H58 -> 61223.24 | I5: ='[1]Data Sheet'!I58 -> 67912.46 | ... K5: ='[1]Data Sheet'!K58 -> 68778.64
A6: Borrowings | B6: ='[1]Data Sheet'!B59 -> 83.78 | C6: ='[1]Data Sheet'!C59 -> 45.72 | D6: ='[1]Data Sheet'!D59 -> 35.92 | E6: ='[1]Data Sheet'!E59 -> 13.44 | F6: ='[1]Data Sheet'!F59 -> 277.45 | G6: ='[1]Data Sheet'!G59 -> 270.83 | H6: ='[1]Data Sheet'!H59 -> 249.44 | I6: ='[1]Data Sheet'!I59 -> 306.04 | ... K6: ='[1]Data Sheet'!K59 -> 284.54
A7: Other Liabilities | B7: ='[1]Data Sheet'!B60 -> 8888.04 | C7: ='[1]Data Sheet'!C60 -> 9439.67 | D7: ='[1]Data Sheet'!D60 -> 11694.85 | E7: ='[1]Data Sheet'!E60 -> 12584.73 | F7: ='[1]Data Sheet'!F60 -> 11760.04 | G7: ='[1]Data Sheet'!G60 -> 13142.59 | H7: ='[1]Data Sheet'!H60 -> 14491.01 | I7: ='[1]Data Sheet'!I60 -> 16369.66 | ... K7: ='[1]Data Sheet'!K60 -> 17688.11
A8: Total | B8: ='[1]Data Sheet'!B61 -> 51651.34 | C8: ='[1]Data Sheet'!C61 -> 55898.32 | D8: ='[1]Data Sheet'!D61 -> 64240.88 | E8: ='[1]Data Sheet'!E61 -> 71739.04 | F8: ='[1]Data Sheet'!F61 -> 77310.75 | G8: ='[1]Data Sheet'!G61 -> 73760.76 | H8: ='[1]Data Sheet'!H61 -> 77196.02 | I8: ='[1]Data Sheet'!I61 -> 85830.96 | ... K8: ='[1]Data Sheet'!K61 -> 88002.7
A10: Net Block | B10: ='[1]Data Sheet'!B62 -> 15106.63 | C10: ='[1]Data Sheet'!C62 -> 15893.48 | D10: ='[1]Data Sheet'!D62 -> 16523.96 | E10: ='[1]Data Sheet'!E62 -> 19374.19 | F10: ='[1]Data Sheet'!F62 -> 21713.34 | G10: ='[1]Data Sheet'!G62 -> 23298.48 | H10: ='[1]Data Sheet'!H62 -> 24231.59 | I10: ='[1]Data Sheet'!I62 -> 25851.27 | ... K10: ='[1]Data Sheet'!K62 -> 21954.85
A11: Capital Work in Progress | B11: ='[1]Data Sheet'!B63 -> 2559.72 | C11: ='[1]Data Sheet'!C63 -> 3729.89 | D11: ='[1]Data Sheet'!D63 -> 5508.33 | E11: ='[1]Data Sheet'!E63 -> 4136.42 | F11: ='[1]Data Sheet'!F63 -> 3256.46 | G11: ='[1]Data Sheet'!G63 -> 4011.29 | H11: ='[1]Data Sheet'!H63 -> 3225.54 | I11: ='[1]Data Sheet'!I63 -> 3003.3 | ... K11: ='[1]Data Sheet'!K63 -> 1090.91
A12: Investments | B12: ='[1]Data Sheet'!B64 -> 11747.59 | C12: ='[1]Data Sheet'!C64 -> 17581.38 | D12: ='[1]Data Sheet'!D64 -> 22052.86 | E12: ='[1]Data Sheet'!E64 -> 25043.49 | F12: ='[1]Data Sheet'!F64 -> 28663.35 | G12: ='[1]Data Sheet'!G64 -> 24870.87 | H12: ='[1]Data Sheet'!H64 -> 24841.01 | I12: ='[1]Data Sheet'!I64 -> 29415.02 | ... K12: ='[1]Data Sheet'!K64 -> 34719.82
A13: Other Assets | B13: ='[1]Data Sheet'!B65 -> 22237.4 | C13: ='[1]Data Sheet'!C65 -> 18693.57 | D13: ='[1]Data Sheet'!D65 -> 20155.73 | E13: ='[1]Data Sheet'!E65 -> 23184.94 | F13: ='[1]Data Sheet'!F65 -> 23677.6 | G13: ='[1]Data Sheet'!G65 -> 21580.12 | H13: ='[1]Data Sheet'!H65 -> 24897.88 | I13: ='[1]Data Sheet'!I65 -> 27561.37 | ... K13: ='[1]Data Sheet'!K65 -> 30237.12
A14: Total | B14: ='[1]Data Sheet'!B66 -> 51651.34 | C14: ='[1]Data Sheet'!C66 -> 55898.32 | D14: ='[1]Data Sheet'!D66 -> 64240.88 | E14: ='[1]Data Sheet'!E66 -> 71739.04 | F14: ='[1]Data Sheet'!F66 -> 77310.75 | G14: ='[1]Data Sheet'!G66 -> 73760.76 | H14: ='[1]Data Sheet'!H66 -> 77196.02 | I14: ='[1]Data Sheet'!I66 -> 85830.96 | ... K14: ='[1]Data Sheet'!K66 -> 88002.7
A16: Working Capital | B16: =B13-B7 -> 13349.36 | C16: =C13-C7 -> 9253.9 | D16: =D13-D7 -> 8460.88 | E16: =E13-E7 -> 10600.21 | F16: =F13-F7 -> 11917.56 | G16: =G13-G7 -> 8437.53 | H16: =H13-H7 -> 10406.87 | I16: =I13-I7 -> 11191.71 | ... K16: =K13-K7 -> 12549.01
A17: Debtors | B17: ='[1]Data Sheet'!B67 -> 1917.18 | C17: ='[1]Data Sheet'!C67 -> 2474.29 | D17: ='[1]Data Sheet'!D67 -> 2682.29 | E17: ='[1]Data Sheet'!E67 -> 4035.28 | F17: ='[1]Data Sheet'!F67 -> 2562.48 | G17: ='[1]Data Sheet'!G67 -> 2501.7 | H17: ='[1]Data Sheet'!H67 -> 2461.9 | I17: ='[1]Data Sheet'!I67 -> 2956.17 | ... K17: ='[1]Data Sheet'!K67 -> 4719.67
A18: Inventory | B18: ='[1]Data Sheet'!B68 -> 9062.1 | C18: ='[1]Data Sheet'!C68 -> 8116.1 | D18: ='[1]Data Sheet'!D68 -> 7495.09 | E18: ='[1]Data Sheet'!E68 -> 7859.56 | F18: ='[1]Data Sheet'!F68 -> 8879.33 | G18: ='[1]Data Sheet'!G68 -> 10397.16 | H18: ='[1]Data Sheet'!H68 -> 10864.15 | I18: ='[1]Data Sheet'!I68 -> 11771.16 | ... K18: ='[1]Data Sheet'!K68 -> 15637.56
A20: Debtor Days | B20: =IF('[1]Profit & Loss'!B4>0,'Balance Sheet'!B17/('[1]Profit & Loss'!B4/365),0) -> 17.854892 | C20: =IF('[1]Profit & Loss'!C4>0,'Balance Sheet'!C17/('[1]Profit & Loss'!C4/365),0) -> 21.116823 | D20: =IF('[1]Profit & Loss'!D4>0,'Balance Sheet'!D17/('[1]Profit & Loss'!D4/365),0) -> 22.53302 | E20: =IF('[1]Profit & Loss'!E4>0,'Balance Sheet'!E17/('[1]Profit & Loss'!E4/365),0) -> 30.469383 | F20: =IF('[1]Profit & Loss'!F4>0,'Balance Sheet'!F17/('[1]Profit & Loss'!F4/365),0) -> 18.938019 | G20: =IF('[1]Profit & Loss'!G4>0,'Balance Sheet'!G17/('[1]Profit & Loss'!G4/365),0) -> 18.537714 | H20: =IF('[1]Profit & Loss'!H4>0,'Balance Sheet'!H17/('[1]Profit & Loss'!H4/365),0) -> 14.817385 | I20: =IF('[1]Profit & Loss'!I4>0,'Balance Sheet'!I17/('[1]Profit & Loss'!I4/365),0) -> 15.214563 | ... K20: =IF('[1]Profit & Loss'!K4>0,'Balance Sheet'!K17/('[1]Profit & Loss'!K4/365),0) -> 22.870462
A21: Inventory Turnover | B21: =IF('Balance Sheet'!B18>0,'[1]Profit & Loss'!B4/'Balance Sheet'!B18,0) -> 4.3248364 | C21: =IF('Balance Sheet'!C18>0,'[1]Profit & Loss'!C4/'Balance Sheet'!C18,0) -> 5.2694767 | D21: =IF('Balance Sheet'!D18>0,'[1]Profit & Loss'!D4/'Balance Sheet'!D18,0) -> 5.7969871 | E21: =IF('Balance Sheet'!E18>0,'[1]Profit & Loss'!E4/'Balance Sheet'!E18,0) -> 6.1504181 | F21: =IF('Balance Sheet'!F18>0,'[1]Profit & Loss'!F4/'Balance Sheet'!F18,0) -> 5.5620976 | G21: =IF('Balance Sheet'!G18>0,'[1]Profit & Loss'!G4/'Balance Sheet'!G18,0) -> 4.737587 | H21: =IF('Balance Sheet'!H18>0,'[1]Profit & Loss'!H4/'Balance Sheet'!H18,0) -> 5.5820787 | I21: =IF('Balance Sheet'!I18>0,'[1]Profit & Loss'!I4/'Balance Sheet'!I18,0) -> 6.0248123 | ... K21: =IF('Balance Sheet'!K18>0,'[1]Profit & Loss'!K4/'Balance Sheet'!K18,0) -> 4.8168218
A23: Return on Equity | B23: =IF(SUM('Balance Sheet'!B4:B5)>0,'[1]Profit & Loss'!B12/SUM('Balance Sheet'!B4:B5),"") -> 0.21894459 | C23: =IF(SUM('Balance Sheet'!C4:C5)>0,'[1]Profit & Loss'!C12/SUM('Balance Sheet'!C4:C5),"") -> 0.22169339 | D23: =IF(SUM('Balance Sheet'!D4:D5)>0,'[1]Profit & Loss'!D12/SUM('Balance Sheet'!D4:D5),"") -> 0.21464819 | E23: =IF(SUM('Balance Sheet'!E4:E5)>0,'[1]Profit & Loss'!E12/SUM('Balance Sheet'!E4:E5),"") -> 0.21292095 | F23: =IF(SUM('Balance Sheet'!F4:F5)>0,'[1]Profit & Loss'!F12/SUM('Balance Sheet'!F4:F5),"") -> 0.23449465 | G23: =IF(SUM('Balance Sheet'!G4:G5)>0,'[1]Profit & Loss'!G12/SUM('Balance Sheet'!G4:G5),"") -> 0.21809064 | H23: =IF(SUM('Balance Sheet'!H4:H5)>0,'[1]Profit & Loss'!H12/SUM('Balance Sheet'!H4:H5),"") -> 0.24405605 | I23: =IF(SUM('Balance Sheet'!I4:I5)>0,'[1]Profit & Loss'!I12/SUM('Balance Sheet'!I4:I5),"") -> 0.27751555 | ... K23: =IF(SUM('Balance Sheet'!K4:K5)>0,'[1]Profit & Loss'!K12/SUM('Balance Sheet'!K4:K5),"") -> 0.49616743
A24: Return on Capital Emp | C24: =IF((B4+B5+B6+C4+C5+C6)>0,('[1]Profit & Loss'!C10+'[1]Profit & Loss'!C9)*2/(B4+B5+B6+C4+C5+C6),"") -> 0.36034518 | D24: =IF((C4+C5+C6+D4+D5+D6)>0,('[1]Profit & Loss'!D10+'[1]Profit & Loss'!D9)*2/(C4+C5+C6+D4+D5+D6),"") -> 0.35400589 | E24: =IF((D4+D5+D6+E4+E5+E6)>0,('[1]Profit & Loss'!E10+'[1]Profit & Loss'!E9)*2/(D4+D5+D6+E4+E5+E6),"") -> 0.34415688 | F24: =IF((E4+E5+E6+F4+F5+F6)>0,('[1]Profit & Loss'!F10+'[1]Profit & Loss'!F9)*2/(E4+E5+E6+F4+F5+F6),"") -> 0.32261652 | G24: =IF((F4+F5+F6+G4+G5+G6)>0,('[1]Profit & Loss'!G10+'[1]Profit & Loss'!G9)*2/(F4+F5+F6+G4+G5+G6),"") -> 0.28527066 | H24: =IF((G4+G5+G6+H4+H5+H6)>0,('[1]Profit & Loss'!H10+'[1]Profit & Loss'!H9)*2/(G4+G5+G6+H4+H5+H6),"") -> 0.33733253 | I24: =IF((H4+H5+H6+I4+I5+I6)>0,('[1]Profit & Loss'!I10+'[1]Profit & Loss'!I9)*2/(H4+H5+H6+I4+I5+I6),"") -> 0.39333609 | J24: =IF((I4+I5+I6+J4+J5+J6)>0,('[1]Profit & Loss'!J10+'[1]Profit & Loss'!J9)*2/(I4+I5+I6+J4+J5+J6),"") -> 0.37429273 | K24: =IF((J4+J5+J6+K4+K5+K6)>0,('[1]Profit & Loss'!K10+'[1]Profit & Loss'!K9)*2/(J4+J5+J6+K4+K5+K6),"") -> 0.57864605

Sheet Historical FS
B2: Historical Financial Statements
B3: ='[2]Data Sheet'!B1 -> ITC LTD
B5: Particulars | C5: ='[2]Data Sheet'!B16 -> 42460 | D5: ='[2]Data Sheet'!C16 -> 42825 | E5: ='[2]Data Sheet'!D16 -> 43190 | F5: ='[2]Data Sheet'!E16 -> 43555 | G5: ='[2]Data Sheet'!F16 -> 43921 | H5: ='[2]Data Sheet'!G16 -> 44286 | I5: ='[2]Data Sheet'!H16 -> 44651 | J5: ='[2]Data Sheet'!I16 -> 45016 | ... L5: ='[2]Data Sheet'!K16 -> 45747 | M5: LTM
A7: # | B7: Income Statement
B8: Sales | C8: =IFERROR('[2]Data Sheet'!B17,0) -> 39192.1 | D8: =IFERROR('[2]Data Sheet'!C17,0) -> 42767.6 | E8: =IFERROR('[2]Data Sheet'!D17,0) -> 43448.94 | F8: =IFERROR('[2]Data Sheet'!E17,0) -> 48339.58 | G8: =IFERROR('[2]Data Sheet'!F17,0) -> 49387.7 | H8: =IFERROR('[2]Data Sheet'!G17,0) -> 49257.45 | I8: =IFERROR('[2]Data Sheet'!H17,0) -> 60644.54 | J8: =IFERROR('[2]Data Sheet'!I17,0) -> 70919.03 | ... L8: =IFERROR('[2]Data Sheet'!K17,0) -> 75323.34 | M8: =IFERROR(SUM('[2]Data Sheet'!H42:K42),0) -> 79040.32
B9: Sales Growth | C9: - | D9: =D8/C8-1 -> 0.09123012 | E9: =E8/D8-1 -> 0.015931219 | F9: =F8/E8-1 -> 0.11256063 | G9: =G8/F8-1 -> 0.021682439 | H9: =H8/G8-1 -> -0.0026372963 | I9: =I8/H8-1 -> 0.23117498 | J9: =J8/I8-1 -> 0.16942152 | K9: =K8/J8-1 -> -0.042119724 | ... M9: =M8/L8-1 -> 0.049346989
B11: COGS | C11: =IFERROR(SUM('[2]Data Sheet'!B18,'[2]Data Sheet'!B20:B22)-1*'[2]Data Sheet'!B19,0) -> 19162.94 | D11: =IFERROR(SUM('[2]Data Sheet'!C18,'[2]Data Sheet'!C20:C22)-1*'[2]Data Sheet'!C19,0) -> 21949.12 | E11: =IFERROR(SUM('[2]Data Sheet'!D18,'[2]Data Sheet'!D20:D22)-1*'[2]Data Sheet'!D19,0) -> 21967.5 | F11: =IFERROR(SUM('[2]Data Sheet'!E18,'[2]Data Sheet'!E20:E22)-1*'[2]Data Sheet'!E19,0) -> 24215.95 | G11: =IFERROR(SUM('[2]Data Sheet'!F18,'[2]Data Sheet'!F20:F22)-1*'[2]Data Sheet'!F19,0) -> 24330.4 | H11: =IFERROR(SUM('[2]Data Sheet'!G18,'[2]Data Sheet'!G20:G22)-1*'[2]Data Sheet'!G19,0) -> 26881.51 | I11: =IFERROR(SUM('[2]Data Sheet'!H18,'[2]Data Sheet'!H20:H22)-1*'[2]Data Sheet'!H19,0) -> 34053.06 | J11: =IFERROR(SUM('[2]Data Sheet'!I18,'[2]Data Sheet'!I20:I22)-1*'[2]Data Sheet'!I19,0) -> 38302.13 | ... L11: =IFERROR(SUM('[2]Data Sheet'!K18,'[2]Data Sheet'!K20:K22)-1*'[2]Data Sheet'!K19,0) -> 41469.21 | M11: =IFERROR(SUM('[2]Data Sheet'!H43:K43),0) -> 52790.48
B12: COGS % Sales | C12: =C11/C8 -> 0.48894905 | D12: =D11/D8 -> 0.51321842 | E12: =E11/E8 -> 0.50559346 | F12: =F11/F8 -> 0.50095491 | G12: =G11/G8 -> 0.49264088 | H12: =H11/H8 -> 0.54573491 | I12: =I11/I8 -> 0.56151898 | J12: =J11/J8 -> 0.54008254 | ... M12: =M11/M8 -> 0.66789304
B14: Gross Profit | C14: =C8-C11 -> 20029.16 | D14: =D8-D11 -> 20818.48 | E14: =E8-E11 -> 21481.44 | F14: =F8-F11 -> 24123.63 | G14: =G8-G11 -> 25057.3 | H14: =H8-H11 -> 22375.94 | I14: =I8-I11 -> 26591.48 | J14: =J8-J11 -> 32616.9 | ... M14: =M8-M11 -> 26249.84
B15: Gross Margins | C15: =C14/C8 -> 0.51105095 | D15: =D14/D8 -> 0.48678158 | E15: =E14/E8 -> 0.49440654 | F15: =F14/F8 -> 0.49904509 | G15: =G14/G8 -> 0.50735912 | H15: =H14/H8 -> 0.45426509 | I15: =I14/I8 -> 0.43848102 | J15: =J14/J8 -> 0.45991746 | ... M15: =M14/M8 -> 0.33210696
B17: Selling & General Expenses | C17: =IFERROR(SUM('[2]Data Sheet'!B23:B24),0) -> 5497.67 | D17: =IFERROR(SUM('[2]Data Sheet'!C23:C24),0) -> 5348.97 | E17: =IFERROR(SUM('[2]Data Sheet'!D23:D24),0) -> 4960.85 | F17: =IFERROR(SUM('[2]Data Sheet'!E23:E24),0) -> 5586.24 | G17: =IFERROR(SUM('[2]Data Sheet'!F23:F24),0) -> 5713.76 | H17: =IFERROR(SUM('[2]Data Sheet'!G23:G24),0) -> 5311.16 | I17: =IFERROR(SUM('[2]Data Sheet'!H23:H24),0) -> 5968.33 | J17: =IFERROR(SUM('[2]Data Sheet'!I23:I24),0) -> 6912.64 | ... L17: =IFERROR(SUM('[2]Data Sheet'!K23:K24),0) -> 8014.68
B18: S&G Exp % Sales | C18: =C17/C11 -> 0.28689074 | D18: =D17/D11 -> 0.24369861 | E18: =E17/E11 -> 0.22582679 | F18: =F17/F11 -> 0.23068432 | G18: =G17/G11 -> 0.23484036 | H18: =H17/H11 -> 0.1975767 | I18: =I17/I11 -> 0.1752656 | J18: =J17/J11 -> 0.18047665 | ... M18: =M17/M11 -> 0
