Workbook
Name IQ_CH: 110000
Name IQ_CQ: 5000
Name IQ_CY: 10000
Name IQ_DAILY: 500000
Name IQ_FH: 100000
Name IQ_FQ: 500
Name IQ_FY: 1000
Name IQ_LTM: 2000
Name IQ_MONTH: 15000
Name IQ_NTM: 6000
Name IQ_WEEK: 50000
Name IQ_YTD: 3000
Name UPDATE: '[1]Data Sheet'!$E$1
Name UPDATE: 'Data Sheet'!$E$1

Sheet Financials

Sheet Historical FS
B2: Historical Financial Statements
B3: ='Data Sheet'!B1 -> ITC LTD
B5: Particulars | C5: ='Data Sheet'!B16 -> 42460 | D5: ='Data Sheet'!C16 -> 42825 | E5: ='Data Sheet'!D16 -> 43190 | F5: ='Data Sheet'!E16 -> 43555 | G5: ='Data Sheet'!F16 -> 43921 | H5: ='Data Sheet'!G16 -> 44286 | I5: ='Data Sheet'!H16 -> 44651 | J5: ='Data Sheet'!I16 -> 45016 | ... L5: ='Data Sheet'!K16 -> 45747 | M5: LTM
A7: # | B7: Income Statement
B8: Sales | C8: =IFERROR('Data Sheet'!B17,0) -> 39192.1 | D8: =IFERROR('Data Sheet'!C17,0) -> 42767.6 | E8: =IFERROR('Data Sheet'!D17,0) -> 43448.94 | F8: =IFERROR('Data Sheet'!E17,0) -> 48339.58 | G8: =IFERROR('Data Sheet'!F17,0) -> 49387.7 | H8: =IFERROR('Data Sheet'!G17,0) -> 49257.45 | I8: =IFERROR('Data Sheet'!H17,0) -> 60644.54 | J8: =IFERROR('Data Sheet'!I17,0) -> 70919.03 | ... L8: =IFERROR('Data Sheet'!K17,0) -> 75323.34 | M8: =IFERROR(SUM('Data Sheet'!H42:K42),0) -> 79040.32
B9: Sales Growth | C9: - | D9: =D8/C8-1 -> 0.09123012 | E9: =E8/D8-1 -> 0.015931219 | F9: =F8/E8-1 -> 0.11256063 | G9: =G8/F8-1 -> 0.021682439 | H9: =H8/G8-1 -> -0.0026372963 | I9: =I8/H8-1 -> 0.23117498 | J9: =J8/I8-1 -> 0.16942152 | K9: =K8/J8-1 -> -0.042119724 | ... M9: =M8/L8-1 -> 0.049346989
B11: COGS | C11: =IFERROR(SUM('Data Sheet'!B18,'Data Sheet'!B20:B22)-1*'Data Sheet'!B19,0) -> 19162.94 | D11: =IFERROR(SUM('Data Sheet'!C18,'Data Sheet'!C20:C22)-1*'Data Sheet'!C19,0) -> 21949.12 | E11: =IFERROR(SUM('Data Sheet'!D18,'Data Sheet'!D20:D22)-1*'Data Sheet'!D19,0) -> 21967.5 | F11: =IFERROR(SUM('Data Sheet'!E18,'Data Sheet'!E20:E22)-1*'Data Sheet'!E19,0) -> 24215.95 | G11: =IFERROR(SUM('Data Sheet'!F18,'Data Sheet'!F20:F22)-1*'Data Sheet'!F19,0) -> 24330.4 | H11: =IFERROR(SUM('Data Sheet'!G18,'Data Sheet'!G20:G22)-1*'Data Sheet'!G19,0) -> 26881.51 | I11: =IFERROR(SUM('Data Sheet'!H18,'Data Sheet'!H20:H22)-1*'Data Sheet'!H19,0) -> 34053.06 | J11: =IFERROR(SUM('Data Sheet'!I18,'Data Sheet'!I20:I22)-1*'Data Sheet'!I19,0) -> 38302.13 | ... L11: =IFERROR(SUM('Data Sheet'!K18,'Data Sheet'!K20:K22)-1*'Data Sheet'!K19,0) -> 41469.21 | M11: =IFERROR(SUM('Data Sheet'!H43:K43),0) -> 52790.48
B12: COGS % Sales | C12: =C11/C8 -> 0.48894905 | D12: =D11/D8 -> 0.51321842 | E12: =E11/E8 -> 0.50559346 | F12: =F11/F8 -> 0.50095491 | G12: =G11/G8 -> 0.49264088 | H12: =H11/H8 -> 0.54573491 | I12: =I11/I8 -> 0.56151898 | J12: =J11/J8 -> 0.54008254 | ... M12: =M11/M8 -> 0.66789304
B14: Gross Profit | C14: =C8-C11 -> 20029.16 | D14: =D8-D11 -> 20818.48 | E14: =E8-E11 -> 21481.44 | F14: =F8-F11 -> 24123.63 | G14: =G8-G11 -> 25057.3 | H14: =H8-H11 -> 22375.94 | I14: =I8-I11 -> 26591.48 | J14: =J8-J11 -> 32616.9 | ... M14: =M8-M11 -> 26249.84
B15: Gross Margins | C15: =C14/C8 -> 0.51105095 | D15: =D14/D8 -> 0.48678158 | E15: =E14/E8 -> 0.49440654 | F15: =F14/F8 -> 0.49904509 | G15: =G14/G8 -> 0.50735912 | H15: =H14/H8 -> 0.45426509 | I15: =I14/I8 -> 0.43848102 | J15: =J14/J8 -> 0.45991746 | ... M15: =M14/M8 -> 0.33210696
B17: Selling & General Expenses | C17: =IFERROR(SUM('Data Sheet'!B23:B24),0) -> 5497.67 | D17: =IFERROR(SUM('Data Sheet'!C23:C24),0) -> 5348.97 | E17: =IFERROR(SUM('Data Sheet'!D23:D24),0) -> 4960.85 | F17: =IFERROR(SUM('Data Sheet'!E23:E24),0) -> 5586.24 | G17: =IFERROR(SUM('Data Sheet'!F23:F24),0) -> 5713.76 | H17: =IFERROR(SUM('Data Sheet'!G23:G24),0) -> 5311.16 | I17: =IFERROR(SUM('Data Sheet'!H23:H24),0) -> 5968.33 | J17: =IFERROR(SUM('Data Sheet'!I23:I24),0) -> 6912.64 | ... L17: =IFERROR(SUM('Data Sheet'!K23:K24),0) -> 8014.68
B18: S&G Exp % Sales | C18: =C17/C11 -> 0.28689074 | D18: =D17/D11 -> 0.24369861 | E18: =E17/E11 -> 0.22582679 | F18: =F17/F11 -> 0.23068432 | G18: =G17/G11 -> 0.23484036 | H18: =H17/H11 -> 0.1975767 | I18: =I17/I11 -> 0.1752656 | J18: =J17/J11 -> 0.18047665 | ... M18: =M17/M11 -> 0
B20: Other Income | C20: =IFERROR('Data Sheet'!B25,0) -> 1483.11 | D20: =IFERROR('Data Sheet'!C25,0) -> 1758.63 | E20: =IFERROR('Data Sheet'!D25,0) -> 2239.81 | F20: =IFERROR('Data Sheet'!E25,0) -> 2080.44 | G20: =IFERROR('Data Sheet'!F25,0) -> 2417.32 | H20: =IFERROR('Data Sheet'!G25,0) -> 2576.95 | I20: =IFERROR('Data Sheet'!H25,0) -> 1909.72 | J20: =IFERROR('Data Sheet'!I25,0) -> 2097.64 | ... L20: =IFERROR('Data Sheet'!K25,0) -> 17794.88
B21: Other Income % Sales | C21: =C20/C8 -> 0.037842065 | D21: =D20/D8 -> 0.041120615 | E21: =E20/E8 -> 0.051550395 | F21: =F20/F8 -> 0.043038024 | G21: =G20/G8 -> 0.04894579 | H21: =H20/H8 -> 0.052315944 | I21: =I20/I8 -> 0.031490386 | J21: =J20/J8 -> 0.029577957 | ... M21: =M20/M8 -> 0
B23: EBITDA | C23: =C14-C17+C20 -> 16014.6 | D23: =D14-D17+D20 -> 17228.14 | E23: =E14-E17+E20 -> 18760.4 | F23: =F14-F17+F20 -> 20617.83 | G23: =G14-G17+G20 -> 21760.86 | H23: =H14-H17+H20 -> 19641.73 | I23: =I14-I17+I20 -> 22532.87 | J23: =J14-J17+J20 -> 27801.9 | ... M23: =M14-M17+M20 -> 26249.84
B24: EBITDA Margins | C24: =C23/C8 -> 0.40861806 | D24: =D23/D8 -> 0.40283158 | E24: =E23/E8 -> 0.43178038 | F24: =F23/F8 -> 0.42652067 | G24: =G23/G8 -> 0.44061295 | H24: =H23/H8 -> 0.39875653 | I24: =I23/I8 -> 0.37155645 | J24: =J23/J8 -> 0.39202313 | ... M24: =M23/M8 -> 0.33210696
B26: Interest | C26: =IFERROR('Data Sheet'!B27,0) -> 78.13 | D26: =IFERROR('Data Sheet'!C27,0) -> 49.03 | E26: =IFERROR('Data Sheet'!D27,0) -> 115.01 | F26: =IFERROR('Data Sheet'!E27,0) -> 71.4 | G26: =IFERROR('Data Sheet'!F27,0) -> 81.38 | H26: =IFERROR('Data Sheet'!G27,0) -> 57.97 | I26: =IFERROR('Data Sheet'!H27,0) -> 59.99 | J26: =IFERROR('Data Sheet'!I27,0) -> 77.77 | ... L26: =IFERROR('Data Sheet'!K27,0) -> 45.06 | M26: =IFERROR(SUM('Data Sheet'!H46:K46),0) -> 51.93
B27: Interest % Sales | C27: =C26/C8 -> 0.001993514 | D27: =D26/D8 -> 0.0011464286 | E27: =E26/E8 -> 0.0026470151 | F27: =F26/F8 -> 0.0014770505 | G27: =G26/G8 -> 0.0016477787 | H27: =H26/H8 -> 0.0011768778 | I27: =I26/I8 -> 0.00098920694 | J27: =J26/J8 -> 0.0010966027 | ... M27: =M26/M8 -> 0.00065700645
B29: Depreciation | C29: =IFERROR('Data Sheet'!B26,0) -> 1077.4 | D29: =IFERROR('Data Sheet'!C26,0) -> 1152.79 | E29: =IFERROR('Data Sheet'!D26,0) -> 1236.28 | F29: =IFERROR('Data Sheet'!E26,0) -> 1396.61 | G29: =IFERROR('Data Sheet'!F26,0) -> 1644.91 | H29: =IFERROR('Data Sheet'!G26,0) -> 1645.59 | I29: =IFERROR('Data Sheet'!H26,0) -> 1732.41 | J29: =IFERROR('Data Sheet'!I26,0) -> 1809.01 | ... L29: =IFERROR('Data Sheet'!K26,0) -> 1646.32 | M29: =IFERROR(SUM('Data Sheet'!H45:K45),0) -> 1666.15
B30: Depreciation%Sales | C30: =C29/C8 -> 0.027490234 | D30: =D29/D8 -> 0.026954751 | E30: =E29/E8 -> 0.028453629 | F30: =F29/F8 -> 0.028891645 | G30: =G29/G8 -> 0.033306066 | H30: =H29/H8 -> 0.033407941 | I30: =I29/I8 -> 0.028566628 | J30: =J29/J8 -> 0.025508104 | ... M30: =M29/M8 -> 0.021079748
B32: Earnings Before Tax | C32: =IFERROR(C23-SUM(C29,C26),0) -> 14859.07 | D32: =IFERROR(D23-SUM(D29,D26),0) -> 16026.32 | E32: =IFERROR(E23-SUM(E29,E26),0) -> 17409.11 | F32: =IFERROR(F23-SUM(F29,F26),0) -> 19149.82 | G32: =IFERROR(G23-SUM(G29,G26),0) -> 20034.57 | H32: =IFERROR(H23-SUM(H29,H26),0) -> 17938.17 | I32: =IFERROR(I23-SUM(I29,I26),0) -> 20740.47 | J32: =IFERROR(J23-SUM(J29,J26),0) -> 25915.12 | ... M32: =IFERROR(M23-SUM(M29,M26),0) -> 24531.76
B33: EBT % Sales | C33: =C32/C8 -> 0.37913432 | D33: =D32/D8 -> 0.3747304 | E33: =E32/E8 -> 0.40067974 | F33: =F32/F8 -> 0.39615197 | G33: =G32/G8 -> 0.4056591 | H33: =H32/H8 -> 0.36417171 | I33: =I32/I8 -> 0.34200062 | J33: =J32/J8 -> 0.36541842 | ... M33: =M32/M8 -> 0.3103702
B35: Tax | C35: =IFERROR('Data Sheet'!B29,0) -> 5358.21 | D35: =IFERROR('Data Sheet'!C29,0) -> 5549.09 | E35: =IFERROR('Data Sheet'!D29,0) -> 5916.43 | F35: =IFERROR('Data Sheet'!E29,0) -> 6313.92 | G35: =IFERROR('Data Sheet'!F29,0) -> 4441.79 | H35: =IFERROR('Data Sheet'!G29,0) -> 4555.29 | I35: =IFERROR('Data Sheet'!H29,0) -> 5237.34 | J35: =IFERROR('Data Sheet'!I29,0) -> 6438.4 | ... L35: =IFERROR('Data Sheet'!K29,0) -> 6890.47 | M35: =IFERROR(SUM('Data Sheet'!H48:K48),0) -> 6948.82
B36: Effective Tax Rate | C36: =C35/C32 -> 0.36060198 | D36: =D35/D32 -> 0.34624855 | E36: =E35/E32 -> 0.33984678 | F36: =F35/F32 -> 0.32971172 | G36: =G35/G32 -> 0.22170628 | H36: =H35/H32 -> 0.25394396 | I36: =I35/I32 -> 0.2525179 | J36: =J35/J32 -> 0.24844184 | ... M36: =M35/M32 -> 0.28325811
B38: Net Profit | C38: =C32-C35 -> 9500.86 | D38: =D32-D35 -> 10477.23 | E38: =E32-E35 -> 11492.68 | F38: =F32-F35 -> 12835.9 | G38: =G32-G35 -> 15592.78 | H38: =H32-H35 -> 13382.88 | I38: =I32-I35 -> 15503.13 | J38: =J32-J35 -> 19476.72 | ... L38: =L32-L35 -> 35052.48 | M38: =IFERROR(SUM('Data Sheet'!H49:K49),0) -> 34899.24
B39: Net Margins | C39: =C38/C8 -> 0.24241773 | D39: =D38/D8 -> 0.24498055 | E39: =E38/E8 -> 0.26451002 | F39: =F38/F8 -> 0.26553603 | G39: =G38/G8 -> 0.31572193 | H39: =H38/H8 -> 0.27169251 | I39: =I38/I8 -> 0.25563934 | J39: =J38/J8 -> 0.2746332 | ... M39: =M38/M8 -> 0.44153718
B41: No of Equity Shares | C41: =IFERROR('Data Sheet'!B93,0) -> 1207.08 | D41: =IFERROR('Data Sheet'!C93,0) -> 1214.74 | E41: =IFERROR('Data Sheet'!D93,0) -> 1220.43 | F41: =IFERROR('Data Sheet'!E93,0) -> 1225.86 | G41: =IFERROR('Data Sheet'!F93,0) -> 1229.22 | H41: =IFERROR('Data Sheet'!G93,0) -> 1230.88 | I41: =IFERROR('Data Sheet'!H93,0) -> 1232.33 | J41: =IFERROR('Data Sheet'!I93,0) -> 1242.8 | ... L41: =IFERROR('Data Sheet'!K93,0) -> 1251.41 | M41: -
B43: Earnings per Share | C43: =C38/C41 -> 7.8709448 | D43: =D38/D41 -> 8.6250803 | E43: =E38/E41 -> 9.4169104 | F43: =F38/F41 -> 10.470935 | G43: =G38/G41 -> 12.685101 | H43: =H38/H41 -> 10.872611 | I43: =I38/I41 -> 12.58034 | J43: =J38/J41 -> 15.671645 | ... L43: =L38/L41 -> 28.010388 | M43: -
B44: EPS Growth % | C44: - | D44: =D43/C43-1 -> 0.095812578 | E44: =E43/D43-1 -> 0.091805542 | F44: =F43/E43-1 -> 0.11192888 | G44: =G43/F43-1 -> 0.21145834 | H44: =H43/G43-1 -> -0.14288334 | I44: =I43/H43-1 -> 0.15706698 | J44: =J43/I43-1 -> 0.24572508 | K44: =K43/J43-1 -> 0.060605506 | L44: =L43/K43-1 -> 0.68519699 | M44: -
B46: Dividend per Share | C46: =IFERROR('Data Sheet'!B31,0)/C41 -> 5.6666667 | D46: =IFERROR('Data Sheet'!C31,0)/D41 -> 4.7500041 | E46: =IFERROR('Data Sheet'!D31,0)/E41 -> 5.1499963 | F46: =IFERROR('Data Sheet'!E31,0)/F41 -> 5.7500041 | G46: =IFERROR('Data Sheet'!F31,0)/G41 -> 10.149998 | H46: =IFERROR('Data Sheet'!G31,0)/H41 -> 10.75 | I46: =IFERROR('Data Sheet'!H31,0)/I41 -> 11.500004 | J46: =IFERROR('Data Sheet'!I31,0)/J41 -> 15.5 | ... L46: =IFERROR('Data Sheet'!K31,0)/L41 -> 14.349997 | M46: -
B47: Dividend payout ratio | C47: =IFERROR(C46/C43,0) -> 0.71994746 | D47: =IFERROR(D46/D43,0) -> 0.55071999 | E47: =IFERROR(E46/E43,0) -> 0.54688811 | F47: =IFERROR(F46/F43,0) -> 0.54913952 | G47: =IFERROR(G46/G43,0) -> 0.8001511 | H47: =IFERROR(H46/H43,0) -> 0.98872291 | I47: =IFERROR(I46/I43,0) -> 0.91412508 | J47: =IFERROR(J46/J43,0) -> 0.98904744 | ... L47: =IFERROR(L46/L43,0) -> 0.51230983 | M47: -
B49: Retained Earnings | C49: =IFERROR(IF(C43>C46,1-C47,0),0) -> 0.28005254 | D49: =IFERROR(IF(D43>D46,1-D47,0),0) -> 0.44928001 | E49: =IFERROR(IF(E43>E46,1-E47,0),0) -> 0.45311189 | F49: =IFERROR(IF(F43>F46,1-F47,0),0) -> 0.45086048 | G49: =IFERROR(IF(G43>G46,1-G47,0),0) -> 0.1998489 | H49: =IFERROR(IF(H43>H46,1-H47,0),0) -> 0.011277094 | I49: =IFERROR(IF(I43>I46,1-I47,0),0) -> 0.085874917 | J49: =IFERROR(IF(J43>J46,1-J47,0),0) -> 0.010952563 | ... L49: =IFERROR(IF(L43>L46,1-L47,0),0) -> 0.48769017 | M49: -
A50: #
B51: Balance Sheet
B52: Equity Share Capital | C52: =IFERROR('Data Sheet'!B57,0) -> 804.72 | D52: =IFERROR('Data Sheet'!C57,0) -> 1214.74 | E52: =IFERROR('Data Sheet'!D57,0) -> 1220.43 | F52: =IFERROR('Data Sheet'!E57,0) -> 1225.86 | G52: =IFERROR('Data Sheet'!F57,0) -> 1229.22 | H52: =IFERROR('Data Sheet'!G57,0) -> 1230.88 | I52: =IFERROR('Data Sheet'!H57,0) -> 1232.33 | J52: =IFERROR('Data Sheet'!I57,0) -> 1242.8 | ... L52: =IFERROR('Data Sheet'!K57,0) -> 1251.41 | M52: -
B53: Reserves | C53: =IFERROR('Data Sheet'!B58,0) -> 41874.8 | D53: =IFERROR('Data Sheet'!C58,0) -> 45198.19 | E53: =IFERROR('Data Sheet'!D58,0) -> 51289.68 | F53: =IFERROR('Data Sheet'!E58,0) -> 57915.01 | G53: =IFERROR('Data Sheet'!F58,0) -> 64044.04 | H53: =IFERROR('Data Sheet'!G58,0) -> 59116.46 | I53: =IFERROR('Data Sheet'!H58,0) -> 61223.24 | J53: =IFERROR('Data Sheet'!I58,0) -> 67912.46 | ... L53: =IFERROR('Data Sheet'!K58,0) -> 68778.64 | M53: -
B54: Borrowings | C54: =IFERROR('Data Sheet'!B59,0) -> 83.78 | D54: =IFERROR('Data Sheet'!C59,0) -> 45.72 | E54: =IFERROR('Data Sheet'!D59,0) -> 35.92 | F54: =IFERROR('Data Sheet'!E59,0) -> 13.44 | G54: =IFERROR('Data Sheet'!F59,0) -> 277.45 | H54: =IFERROR('Data Sheet'!G59,0) -> 270.83 | I54: =IFERROR('Data Sheet'!H59,0) -> 249.44 | J54: =IFERROR('Data Sheet'!I59,0) -> 306.04 | ... L54: =IFERROR('Data Sheet'!K59,0) -> 284.54 | M54: -
B55: Other Liabilities | C55: =IFERROR('Data Sheet'!B60,0) -> 8888.04 | D55: =IFERROR('Data Sheet'!C60,0) -> 9439.67 | E55: =IFERROR('Data Sheet'!D60,0) -> 11694.85 | F55: =IFERROR('Data Sheet'!E60,0) -> 12584.73 | G55: =IFERROR('Data Sheet'!F60,0) -> 11760.04 | H55: =IFERROR('Data Sheet'!G60,0) -> 13142.59 | I55: =IFERROR('Data Sheet'!H60,0) -> 14491.01 | J55: =IFERROR('Data Sheet'!I60,0) -> 16369.66 | ... L55: =IFERROR('Data Sheet'!K60,0) -> 17688.11 | M55: -
B56: Total Liabilities | C56: =IFERROR('Data Sheet'!B61,0) -> 51651.34 | D56: =IFERROR('Data Sheet'!C61,0) -> 55898.32 | E56: =IFERROR('Data Sheet'!D61,0) -> 64240.88 | F56: =IFERROR('Data Sheet'!E61,0) -> 71739.04 | G56: =IFERROR('Data Sheet'!F61,0) -> 77310.75 | H56: =IFERROR('Data Sheet'!G61,0) -> 73760.76 | I56: =IFERROR('Data Sheet'!H61,0) -> 77196.02 | J56: =IFERROR('Data Sheet'!I61,0) -> 85830.96 | ... L56: =IFERROR('Data Sheet'!K61,0) -> 88002.7 | M56: -
B58: Fixed Assets Net Block | C58: =IFERROR('Data Sheet'!B62,0) -> 15106.63 | D58: =IFERROR('Data Sheet'!C62,0) -> 15893.48 | E58: =IFERROR('Data Sheet'!D62,0) -> 16523.96 | F58: =IFERROR('Data Sheet'!E62,0) -> 19374.19 | G58: =IFERROR('Data Sheet'!F62,0) -> 21713.34 | H58: =IFERROR('Data Sheet'!G62,0) -> 23298.48 | I58: =IFERROR('Data Sheet'!H62,0) -> 24231.59 | J58: =IFERROR('Data Sheet'!I62,0) -> 25851.27 | ... L58: =IFERROR('Data Sheet'!K62,0) -> 21954.85 | M58: -
...

Sheet Common Size Statement
B2: Common Size Statement
B3: ='Data Sheet'!B1 -> ITC LTD
A5: # | B5: ="Common Size Income Statement"&" "&"- "&'Data Sheet'!$B$1 -> Common Size Income Statement - ITC LTD
B7: Particulars | C7: ='Data Sheet'!B16 -> 42460 | D7: ='Data Sheet'!C16 -> 42825 | E7: ='Data Sheet'!D16 -> 43190 | F7: ='Data Sheet'!E16 -> 43555 | G7: ='Data Sheet'!F16 -> 43921 | H7: ='Data Sheet'!G16 -> 44286 | I7: ='Data Sheet'!H16 -> 44651 | J7: ='Data Sheet'!I16 -> 45016 | ... L7: ='Data Sheet'!K16 -> 45747
B9: ='Data Sheet'!A17 -> Sales | C9: ='Data Sheet'!B17/'Data Sheet'!B$17 -> 1 | D9: ='Data Sheet'!C17/'Data Sheet'!C$17 -> 1 | E9: ='Data Sheet'!D17/'Data Sheet'!D$17 -> 1 | F9: ='Data Sheet'!E17/'Data Sheet'!E$17 -> 1 | G9: ='Data Sheet'!F17/'Data Sheet'!F$17 -> 1 | H9: ='Data Sheet'!G17/'Data Sheet'!G$17 -> 1 | I9: ='Data Sheet'!H17/'Data Sheet'!H$17 -> 1 | J9: ='Data Sheet'!I17/'Data Sheet'!I$17 -> 1 | ... L9: ='Data Sheet'!K17/'Data Sheet'!K$17 -> 1
B10: ='Data Sheet'!A18 -> Raw Material Cost | C10: ='Data Sheet'!B18/'Data Sheet'!B$17 -> 0.35119016 | D10: ='Data Sheet'!C18/'Data Sheet'!C$17 -> 0.36140887 | E10: ='Data Sheet'!D18/'Data Sheet'!D$17 -> 0.3412677 | F10: ='Data Sheet'!E18/'Data Sheet'!E$17 -> 0.36457743 | G10: ='Data Sheet'!F18/'Data Sheet'!F$17 -> 0.36544727 | H10: ='Data Sheet'!G18/'Data Sheet'!G$17 -> 0.42179833 | I10: ='Data Sheet'!H18/'Data Sheet'!H$17 -> 0.44638924 | J10: ='Data Sheet'!I18/'Data Sheet'!I$17 -> 0.41405473 | ... L10: ='Data Sheet'!K18/'Data Sheet'!K$17 -> 0.4341864
B11: ='Data Sheet'!A19 -> Change in Inventory | C11: ='Data Sheet'!B19/'Data Sheet'!B$17 -> 0.0049851883 | D11: ='Data Sheet'!C19/'Data Sheet'!C$17 -> -0.013855582 | E11: ='Data Sheet'!D19/'Data Sheet'!D$17 -> -0.023654432 | F11: ='Data Sheet'!E19/'Data Sheet'!E$17 -> 0.0042033878 | G11: ='Data Sheet'!F19/'Data Sheet'!F$17 -> 0.014236946 | H11: ='Data Sheet'!G19/'Data Sheet'!G$17 -> 0.013099947 | I11: ='Data Sheet'!H19/'Data Sheet'!H$17 -> 0.011311818 | J11: ='Data Sheet'!I19/'Data Sheet'!I$17 -> 0.0050563297 | ... L11: ='Data Sheet'!K19/'Data Sheet'!K$17 -> 0.0096338001
B12: ='Data Sheet'!A20 -> Power and Fuel | C12: ='Data Sheet'!B20/'Data Sheet'!B$17 -> 0.014591716 | D12: ='Data Sheet'!C20/'Data Sheet'!C$17 -> 0.013662913 | E12: ='Data Sheet'!D20/'Data Sheet'!D$17 -> 0.015040643 | F12: ='Data Sheet'!E20/'Data Sheet'!E$17 -> 0.01544759 | G12: ='Data Sheet'!F20/'Data Sheet'!F$17 -> 0.015810617 | H12: ='Data Sheet'!G20/'Data Sheet'!G$17 -> 0.014202116 | I12: ='Data Sheet'!H20/'Data Sheet'!H$17 -> 0.01467189 | J12: ='Data Sheet'!I20/'Data Sheet'!I$17 -> 0.017376718 | ... L12: ='Data Sheet'!K20/'Data Sheet'!K$17 -> 0.012948842
B13: ='Data Sheet'!A21 -> Other Mfr. Exp | C13: ='Data Sheet'!B21/'Data Sheet'!B$17 -> 0.040354816 | D13: ='Data Sheet'!C21/'Data Sheet'!C$17 -> 0.039373264 | E13: ='Data Sheet'!D21/'Data Sheet'!D$17 -> 0.039071609 | F13: ='Data Sheet'!E21/'Data Sheet'!E$17 -> 0.038705549 | G13: ='Data Sheet'!F21/'Data Sheet'!F$17 -> 0.038638973 | H13: ='Data Sheet'!G21/'Data Sheet'!G$17 -> 0.032222131 | I13: ='Data Sheet'!H21/'Data Sheet'!H$17 -> 0.031126792 | J13: ='Data Sheet'!I21/'Data Sheet'!I$17 -> 0.032823348 | ... L13: ='Data Sheet'!K21/'Data Sheet'!K$17 -> 0.031137228
B14: ='Data Sheet'!A22 -> Employee Cost | C14: ='Data Sheet'!B22/'Data Sheet'!B$17 -> 0.087797541 | D14: ='Data Sheet'!C22/'Data Sheet'!C$17 -> 0.084917788 | E14: ='Data Sheet'!D22/'Data Sheet'!D$17 -> 0.086559074 | F14: ='Data Sheet'!E22/'Data Sheet'!E$17 -> 0.086427727 | G14: ='Data Sheet'!F22/'Data Sheet'!F$17 -> 0.086980969 | H14: ='Data Sheet'!G22/'Data Sheet'!G$17 -> 0.090612283 | I14: ='Data Sheet'!H22/'Data Sheet'!H$17 -> 0.080642874 | J14: ='Data Sheet'!I22/'Data Sheet'!I$17 -> 0.080884073 | ... L14: ='Data Sheet'!K22/'Data Sheet'!K$17 -> 0.0819106
B15: ='Data Sheet'!A23 -> Selling and admin | C15: ='Data Sheet'!B23/'Data Sheet'!B$17 -> 0.10874079 | D15: ='Data Sheet'!C23/'Data Sheet'!C$17 -> 0.09773146 | E15: ='Data Sheet'!D23/'Data Sheet'!D$17 -> 0.091023394 | F15: ='Data Sheet'!E23/'Data Sheet'!E$17 -> 0.094051086 | G15: ='Data Sheet'!F23/'Data Sheet'!F$17 -> 0.090885585 | H15: ='Data Sheet'!G23/'Data Sheet'!G$17 -> 0.086012776 | I15: ='Data Sheet'!H23/'Data Sheet'!H$17 -> 0.080112406 | J15: ='Data Sheet'!I23/'Data Sheet'!I$17 -> 0.079020821 | ... L15: ='Data Sheet'!K23/'Data Sheet'!K$17 -> 0.076912282
B16: ='Data Sheet'!A24 -> Other Expenses | C16: ='Data Sheet'!B24/'Data Sheet'!B$17 -> 0.031534161 | D16: ='Data Sheet'!C24/'Data Sheet'!C$17 -> 0.027339154 | E16: ='Data Sheet'!D24/'Data Sheet'!D$17 -> 0.023153154 | F16: ='Data Sheet'!E24/'Data Sheet'!E$17 -> 0.021511358 | G16: ='Data Sheet'!F24/'Data Sheet'!F$17 -> 0.024806379 | H16: ='Data Sheet'!G24/'Data Sheet'!G$17 -> 0.021811726 | I16: ='Data Sheet'!H24/'Data Sheet'!H$17 -> 0.018302555 | J16: ='Data Sheet'!I24/'Data Sheet'!I$17 -> 0.018451465 | ... L16: ='Data Sheet'!K24/'Data Sheet'!K$17 -> 0.02949139
B17: ='Data Sheet'!A25 -> Other Income | C17: ='Data Sheet'!B25/'Data Sheet'!B$17 -> 0.037842065 | D17: ='Data Sheet'!C25/'Data Sheet'!C$17 -> 0.041120615 | E17: ='Data Sheet'!D25/'Data Sheet'!D$17 -> 0.051550395 | F17: ='Data Sheet'!E25/'Data Sheet'!E$17 -> 0.043038024 | G17: ='Data Sheet'!F25/'Data Sheet'!F$17 -> 0.04894579 | H17: ='Data Sheet'!G25/'Data Sheet'!G$17 -> 0.052315944 | I17: ='Data Sheet'!H25/'Data Sheet'!H$17 -> 0.031490386 | J17: ='Data Sheet'!I25/'Data Sheet'!I$17 -> 0.029577957 | ... L17: ='Data Sheet'!K25/'Data Sheet'!K$17 -> 0.23624656
B18: ='Data Sheet'!A26 -> Depreciation | C18: ='Data Sheet'!B26/'Data Sheet'!B$17 -> 0.027490234 | D18: ='Data Sheet'!C26/'Data Sheet'!C$17 -> 0.026954751 | E18: ='Data Sheet'!D26/'Data Sheet'!D$17 -> 0.028453629 | F18: ='Data Sheet'!E26/'Data Sheet'!E$17 -> 0.028891645 | G18: ='Data Sheet'!F26/'Data Sheet'!F$17 -> 0.033306066 | H18: ='Data Sheet'!G26/'Data Sheet'!G$17 -> 0.033407941 | I18: ='Data Sheet'!H26/'Data Sheet'!H$17 -> 0.028566628 | J18: ='Data Sheet'!I26/'Data Sheet'!I$17 -> 0.025508104 | ... L18: ='Data Sheet'!K26/'Data Sheet'!K$17 -> 0.021856705
B19: ='Data Sheet'!A27 -> Interest | C19: ='Data Sheet'!B27/'Data Sheet'!B$17 -> 0.001993514 | D19: ='Data Sheet'!C27/'Data Sheet'!C$17 -> 0.0011464286 | E19: ='Data Sheet'!D27/'Data Sheet'!D$17 -> 0.0026470151 | F19: ='Data Sheet'!E27/'Data Sheet'!E$17 -> 0.0014770505 | G19: ='Data Sheet'!F27/'Data Sheet'!F$17 -> 0.0016477787 | H19: ='Data Sheet'!G27/'Data Sheet'!G$17 -> 0.0011768778 | I19: ='Data Sheet'!H27/'Data Sheet'!H$17 -> 0.00098920694 | J19: ='Data Sheet'!I27/'Data Sheet'!I$17 -> 0.0010966027 | ... L19: ='Data Sheet'!K27/'Data Sheet'!K$17 -> 0.00059822095
B20: ='Data Sheet'!A28 -> Profit before tax | C20: ='Data Sheet'!B28/'Data Sheet'!B$17 -> 0.37913432 | D20: ='Data Sheet'!C28/'Data Sheet'!C$17 -> 0.3747304 | E20: ='Data Sheet'!D28/'Data Sheet'!D$17 -> 0.40067974 | F20: ='Data Sheet'!E28/'Data Sheet'!E$17 -> 0.39615197 | G20: ='Data Sheet'!F28/'Data Sheet'!F$17 -> 0.4056591 | H20: ='Data Sheet'!G28/'Data Sheet'!G$17 -> 0.36417171 | I20: ='Data Sheet'!H28/'Data Sheet'!H$17 -> 0.34200062 | J20: ='Data Sheet'!I28/'Data Sheet'!I$17 -> 0.36541842 | ... L20: ='Data Sheet'!K28/'Data Sheet'!K$17 -> 0.55683869
... B23: ='Data Sheet'!A31 -> Dividend Amount | C23: ='Data Sheet'!B31/'Data Sheet'!B$17 -> 0.17452803 | D23: ='Data Sheet'!C31/'Data Sheet'!C$17 -> 0.13491568 | E23: ='Data Sheet'!D31/'Data Sheet'!D$17 -> 0.14465738 | F23: ='Data Sheet'!E31/'Data Sheet'!E$17 -> 0.14581633 | G23: ='Data Sheet'!F31/'Data Sheet'!F$17 -> 0.25262525 | H23: ='Data Sheet'!G31/'Data Sheet'!G$17 -> 0.2686286 | I23: ='Data Sheet'!H31/'Data Sheet'!H$17 -> 0.23368633 | J23: ='Data Sheet'!I31/'Data Sheet'!I$17 -> 0.27162526 | ... L23: ='Data Sheet'!K31/'Data Sheet'!K$17 -> 0.23840857
B25: ='Data Sheet'!A34 -> EBITDA | C25: ='Data Sheet'!B34/'Data Sheet'!B$17 -> 0.40861806 | D25: ='Data Sheet'!C34/'Data Sheet'!C$17 -> 0.40283158 | E25: ='Data Sheet'!D34/'Data Sheet'!D$17 -> 0.43178038 | F25: ='Data Sheet'!E34/'Data Sheet'!E$17 -> 0.42652067 | G25: ='Data Sheet'!F34/'Data Sheet'!F$17 -> 0.44061295 | H25: ='Data Sheet'!G34/'Data Sheet'!G$17 -> 0.39875653 | I25: ='Data Sheet'!H34/'Data Sheet'!H$17 -> 0.37155645 | J25: ='Data Sheet'!I34/'Data Sheet'!I$17 -> 0.39202313 | ... L25: ='Data Sheet'!K34/'Data Sheet'!K$17 -> 0.57929362
A27: # | B27: ="Common Size Balance Sheet"&" "&"- "&'Data Sheet'!$B$1 -> Common Size Balance Sheet - ITC LTD
B29: Particulars | C29: ='Data Sheet'!B56 -> 42460 | D29: ='Data Sheet'!C56 -> 42825 | E29: ='Data Sheet'!D56 -> 43190 | F29: ='Data Sheet'!E56 -> 43555 | G29: ='Data Sheet'!F56 -> 43921 | H29: ='Data Sheet'!G56 -> 44286 | I29: ='Data Sheet'!H56 -> 44651 | J29: ='Data Sheet'!I56 -> 45016 | ... L29: ='Data Sheet'!K56 -> 45747
B31: Total Liabilities | C31: ='Data Sheet'!B61/'Data Sheet'!B$61 -> 1 | D31: ='Data Sheet'!C61/'Data Sheet'!C$61 -> 1 | E31: ='Data Sheet'!D61/'Data Sheet'!D$61 -> 1 | F31: ='Data Sheet'!E61/'Data Sheet'!E$61 -> 1 | G31: ='Data Sheet'!F61/'Data Sheet'!F$61 -> 1 | H31: ='Data Sheet'!G61/'Data Sheet'!G$61 -> 1 | I31: ='Data Sheet'!H61/'Data Sheet'!H$61 -> 1 | J31: ='Data Sheet'!I61/'Data Sheet'!I$61 -> 1 | ... L31: ='Data Sheet'!K61/'Data Sheet'!K$61 -> 1
B32: ='Data Sheet'!A57 -> Equity Share Capital | C32: ='Data Sheet'!B57/'Data Sheet'!B$61 -> 0.015579847 | D32: ='Data Sheet'!C57/'Data Sheet'!C$61 -> 0.021731243 | E32: ='Data Sheet'!D57/'Data Sheet'!D$61 -> 0.018997716 | F32: ='Data Sheet'!E57/'Data Sheet'!E$61 -> 0.017087767 | G32: ='Data Sheet'!F57/'Data Sheet'!F$61 -> 0.015899729 | H32: ='Data Sheet'!G57/'Data Sheet'!G$61 -> 0.016687464 | I32: ='Data Sheet'!H57/'Data Sheet'!H$61 -> 0.015963647 | J32: ='Data Sheet'!I57/'Data Sheet'!I$61 -> 0.014479624 | ... L32: ='Data Sheet'!K57/'Data Sheet'!K$61 -> 0.014220132
B33: ='Data Sheet'!A58 -> Reserves | C33: ='Data Sheet'!B58/'Data Sheet'!B$61 -> 0.8107205 | D33: ='Data Sheet'!C58/'Data Sheet'!C$61 -> 0.80857868 | E33: ='Data Sheet'!D58/'Data Sheet'!D$61 -> 0.79839629 | F33: ='Data Sheet'!E58/'Data Sheet'!E$61 -> 0.80730116 | G33: ='Data Sheet'!F58/'Data Sheet'!F$61 -> 0.8283976 | H33: ='Data Sheet'!G58/'Data Sheet'!G$61 -> 0.80146219 | I33: ='Data Sheet'!H58/'Data Sheet'!H$61 -> 0.79308804 | J33: ='Data Sheet'!I58/'Data Sheet'!I$61 -> 0.791235 | ... L33: ='Data Sheet'!K58/'Data Sheet'!K$61 -> 0.78155148
B34: ='Data Sheet'!A59 -> Borrowings | C34: ='Data Sheet'!B59/'Data Sheet'!B$61 -> 0.0016220296 | D34: ='Data Sheet'!C59/'Data Sheet'!C$61 -> 0.00081791367 | E34: ='Data Sheet'!D59/'Data Sheet'!D$61 -> 0.00055914552 | F34: ='Data Sheet'!E59/'Data Sheet'!E$61 -> 0.00018734569 | G34: ='Data Sheet'!F59/'Data Sheet'!F$61 -> 0.0035887635 | H34: ='Data Sheet'!G59/'Data Sheet'!G$61 -> 0.0036717355 | I34: ='Data Sheet'!H59/'Data Sheet'!H$61 -> 0.0032312547 | J34: ='Data Sheet'!I59/'Data Sheet'!I$61 -> 0.0035656132 | ... L34: ='Data Sheet'!K59/'Data Sheet'!K$61 -> 0.0032333099
B35: ='Data Sheet'!A60 -> Other Liabilities | C35: ='Data Sheet'!B60/'Data Sheet'!B$61 -> 0.17207763 | D35: ='Data Sheet'!C60/'Data Sheet'!C$61 -> 0.16887216 | E35: ='Data Sheet'!D60/'Data Sheet'!D$61 -> 0.18204685 | F35: ='Data Sheet'!E60/'Data Sheet'!E$61 -> 0.17542373 | G35: ='Data Sheet'!F60/'Data Sheet'!F$61 -> 0.1521139 | H35: ='Data Sheet'!G60/'Data Sheet'!G$61 -> 0.17817861 | I35: ='Data Sheet'!H60/'Data Sheet'!H$61 -> 0.18771706 | J35: ='Data Sheet'!I60/'Data Sheet'!I$61 -> 0.19071976 | ... L35: ='Data Sheet'!K60/'Data Sheet'!K$61 -> 0.20099508
B37: Total Assets | C37: ='Data Sheet'!B76/'Data Sheet'!B$76 -> 1 | D37: ='Data Sheet'!C76/'Data Sheet'!C$76 -> 1 | E37: ='Data Sheet'!D76/'Data Sheet'!D$76 -> 1 | F37: ='Data Sheet'!E76/'Data Sheet'!E$76 -> 1 | G37: ='Data Sheet'!F76/'Data Sheet'!F$76 -> 1 | H37: ='Data Sheet'!G76/'Data Sheet'!G$76 -> 1 | I37: ='Data Sheet'!H76/'Data Sheet'!H$76 -> 1 | J37: ='Data Sheet'!I76/'Data Sheet'!I$76 -> 1 | ... L37: ='Data Sheet'!K76/'Data Sheet'!K$76 -> 1
B38: ='Data Sheet'!A62 -> Net Block | C38: ='Data Sheet'!B62/'Data Sheet'!B$76 -> 0.29247315 | D38: ='Data Sheet'!C62/'Data Sheet'!C$76 -> 0.2843284 | E38: ='Data Sheet'!D62/'Data Sheet'!D$76 -> 0.25721877 | F38: ='Data Sheet'!E62/'Data Sheet'!E$76 -> 0.27006481 | G38: ='Data Sheet'!F62/'Data Sheet'!F$76 -> 0.28085797 | H38: ='Data Sheet'!G62/'Data Sheet'!G$76 -> 0.31586551 | I38: ='Data Sheet'!H62/'Data Sheet'!H$76 -> 0.31389688 | J38: ='Data Sheet'!I62/'Data Sheet'!I$76 -> 0.30118817 | ... L38: ='Data Sheet'!K62/'Data Sheet'!K$76 -> 0.24947928
B39: ='Data Sheet'!A63 -> Capital Work in Progress | C39: ='Data Sheet'!B63/'Data Sheet'!B$76 -> 0.049557669 | D39: ='Data Sheet'!C63/'Data Sheet'!C$76 -> 0.066726335 | E39: ='Data Sheet'!D63/'Data Sheet'!D$76 -> 0.085744934 | F39: ='Data Sheet'!E63/'Data Sheet'!E$76 -> 0.057659261 | G39: ='Data Sheet'!F63/'Data Sheet'!F$76 -> 0.042121697 | H39: ='Data Sheet'!G63/'Data Sheet'!G$76 -> 0.054382439 | I39: ='Data Sheet'!H63/'Data Sheet'!H$76 -> 0.04178376 | J39: ='Data Sheet'!I63/'Data Sheet'!I$76 -> 0.03499087 | ... L39: ='Data Sheet'!K63/'Data Sheet'!K$76 -> 0.012396324
B40: ='Data Sheet'!A64 -> Investments | C40: ='Data Sheet'!B64/'Data Sheet'!B$76 -> 0.22744018 | D40: ='Data Sheet'!C64/'Data Sheet'!C$76 -> 0.3145243 | E40: ='Data Sheet'!D64/'Data Sheet'!D$76 -> 0.3432839 | F40: ='Data Sheet'!E64/'Data Sheet'!E$76 -> 0.34909151 | G40: ='Data Sheet'!F64/'Data Sheet'!F$76 -> 0.37075504 | H40: ='Data Sheet'!G64/'Data Sheet'!G$76 -> 0.33718294 | I40: ='Data Sheet'!H64/'Data Sheet'!H$76 -> 0.32179133 | J40: ='Data Sheet'!I64/'Data Sheet'!I$76 -> 0.34270874 | ... L40: ='Data Sheet'!K64/'Data Sheet'!K$76 -> 0.3945313
B41: ='Data Sheet'!A65 -> Other Assets | C41: ='Data Sheet'!B74/'Data Sheet'!B$76 -> 0.10057474 | D41: ='Data Sheet'!C74/'Data Sheet'!C$76 -> 0.09187718 | E41: ='Data Sheet'!D74/'Data Sheet'!D$76 -> 0.11019074 | F41: ='Data Sheet'!E74/'Data Sheet'!E$76 -> 0.099500495 | G41: ='Data Sheet'!F74/'Data Sheet'!F$76 -> 0.064136617 | H41: ='Data Sheet'!G74/'Data Sheet'!G$76 -> 0.054530891 | I41: ='Data Sheet'!H74/'Data Sheet'!H$76 -> 0.089608376 | J41: ='Data Sheet'!I74/'Data Sheet'!I$76 -> 0.092668776 | ... L41: ='Data Sheet'!K74/'Data Sheet'!K$76 -> 0.066674432
B42: ='Data Sheet'!A67 -> Receivables | C42: ='Data Sheet'!B67/'Data Sheet'!B$76 -> 0.03711772 | D42: ='Data Sheet'!C67/'Data Sheet'!C$76 -> 0.044264121 | E42: ='Data Sheet'!D67/'Data Sheet'!D$76 -> 0.041753631 | F42: ='Data Sheet'!E67/'Data Sheet'!E$76 -> 0.056249428 | G42: ='Data Sheet'!F67/'Data Sheet'!F$76 -> 0.033145196 | H42: ='Data Sheet'!G67/'Data Sheet'!G$76 -> 0.033916408 | I42: ='Data Sheet'!H67/'Data Sheet'!H$76 -> 0.031891541 | J42: ='Data Sheet'!I67/'Data Sheet'!I$76 -> 0.034441768 | ... L42: ='Data Sheet'!K67/'Data Sheet'!K$76 -> 0.053630968
B43: ='Data Sheet'!A68 -> Inventory | C43: ='Data Sheet'!B68/'Data Sheet'!B$76 -> 0.17544753 | D43: ='Data Sheet'!C68/'Data Sheet'!C$76 -> 0.14519399 | E43: ='Data Sheet'!D68/'Data Sheet'!D$76 -> 0.11667166 | F43: ='Data Sheet'!E68/'Data Sheet'!E$76 -> 0.10955764 | G43: ='Data Sheet'!F68/'Data Sheet'!F$76 -> 0.11485246 | H43: ='Data Sheet'!G68/'Data Sheet'!G$76 -> 0.14095788 | I43: ='Data Sheet'!H68/'Data Sheet'!H$76 -> 0.14073459 | J43: ='Data Sheet'!I68/'Data Sheet'!I$76 -> 0.13714352 | ... L43: ='Data Sheet'!K68/'Data Sheet'!K$76 -> 0.17769409
B44: ='Data Sheet'!A69 -> Cash & Bank | C44: ='Data Sheet'!B69/'Data Sheet'!B$76 -> 0.11738902 | D44: ='Data Sheet'!C69/'Data Sheet'!C$76 -> 0.053085674 | E44: ='Data Sheet'!D69/'Data Sheet'!D$76 -> 0.045136368 | F44: ='Data Sheet'!E69/'Data Sheet'!E$76 -> 0.057876855 | G44: ='Data Sheet'!F69/'Data Sheet'!F$76 -> 0.094131023 | H44: ='Data Sheet'!G69/'Data Sheet'!G$76 -> 0.063163937 | I44: ='Data Sheet'!H69/'Data Sheet'!H$76 -> 0.060293523 | J44: ='Data Sheet'!I69/'Data Sheet'!I$76 -> 0.056858155 | ... L44: ='Data Sheet'!K69/'Data Sheet'!K$76 -> 0.045593601

Sheet Ratios
B2: Ratio Analysis
B3: ='Data Sheet'!B1 -> ITC LTD
D5: Post Covid-19 Years
B6: Particulars | C6: ='Data Sheet'!G16 -> 44286 | D6: ='Data Sheet'!H16 -> 44651 | E6: ='Data Sheet'!I16 -> 45016 | F6: ='Data Sheet'!J16 -> 45382 | G6: ='Data Sheet'!K16 -> 45747 | I6: Trend | K6: Mean | L6: Industry Avg
A8: # | B8: Growth Ratios
B9: SalesGrowth | C9: =IFERROR('Historical FS'!H9,0) -> -0.0026372963 | D9: =IFERROR('Historical FS'!I9,0) -> 0.23117498 | E9: =IFERROR('Historical FS'!J9,0) -> 0.16942152 | F9: =IFERROR('Historical FS'!K9,0) -> -0.042119724 | G9: =IFERROR('Historical FS'!L9,0) -> 0.10880596 | K9: =AVERAGE(C9:G9) -> 0.092929087 | L9: 0.1
B10: GrossMarginGrowth | C10: =IFERROR(('Historical FS'!H14/'Historical FS'!G14)-1,0) -> -0.10700914 | D10: =IFERROR(('Historical FS'!I14/'Historical FS'!H14)-1,0) -> 0.18839611 | E10: =IFERROR(('Historical FS'!J14/'Historical FS'!I14)-1,0) -> 0.22659213 | F10: =IFERROR(('Historical FS'!K14/'Historical FS'!J14)-1,0) -> -0.01075976 | G10: =IFERROR(('Historical FS'!L14/'Historical FS'!K14)-1,0) -> 0.049221548 | K10: =AVERAGE(C10:G10) -> 0.069288177 | L10: -
B11: EBITDA Growth | C11: =IFERROR(('Historical FS'!H23/'Historical FS'!G23)-1,0) -> -0.09738264 | D11: =IFERROR(('Historical FS'!I23/'Historical FS'!H23)-1,0) -> 0.14719376 | E11: =IFERROR(('Historical FS'!J23/'Historical FS'!I23)-1,0) -> 0.2338375 | F11: =IFERROR(('Historical FS'!K23/'Historical FS'!J23)-1,0) -> 0.025756513 | G11: =IFERROR(('Historical FS'!L23/'Historical FS'!K23)-1,0) -> 0.53006384 | K11: =AVERAGE(C11:G11) -> 0.16789379 | L11: -
B12: EBT Growth | C12: =IFERROR(('Historical FS'!H32/'Historical FS'!G32)-1,0) -> -0.10463913 | D12: =IFERROR(('Historical FS'!I32/'Historical FS'!H32)-1,0) -> 0.15621995 | E12: =IFERROR(('Historical FS'!J32/'Historical FS'!I32)-1,0) -> 0.24949531 | F12: =IFERROR(('Historical FS'!K32/'Historical FS'!J32)-1,0) -> 0.040350961 | G12: =IFERROR(('Historical FS'!L32/'Historical FS'!K32)-1,0) -> 0.55570009 | K12: =AVERAGE(C12:G12) -> 0.17942544 | L12: 0.034
B13: Net Profit Growth | C13: =IFERROR(('Historical FS'!H38/'Historical FS'!G38)-1,0) -> -0.14172585 | D13: =IFERROR(('Historical FS'!I38/'Historical FS'!H38)-1,0) -> 0.15843002 | E13: =IFERROR(('Historical FS'!J38/'Historical FS'!I38)-1,0) -> 0.25630889 | F13: =IFERROR(('Historical FS'!K38/'Historical FS'!J38)-1,0) -> 0.065444284 | G13: =IFERROR(('Historical FS'!L38/'Historical FS'!K38)-1,0) -> 0.68916543 | K13: =AVERAGE(C13:G13) -> 0.20552456 | L13: 0.041
B14: Self Sustained Growth Rate | C14: =C27*C28 -> 0.0025008559 | D14: =D27*D28 -> 0.021316433 | E14: =E27*E28 -> 0.0030846533 | F14: =F27*F28 -> 0.048114942 | G14: =G27*G28 -> 0.24410592 | K14: =AVERAGE(C14:G14) -> 0.063824562 | L14: -
B15: Dividend Growth | C15: =IFERROR(('Data Sheet'!G34/'Data Sheet'!F34)-1,0) -> -0.09738264 | D15: =IFERROR(('Data Sheet'!H34/'Data Sheet'!G34)-1,0) -> 0.14719376 | E15: =IFERROR(('Data Sheet'!I34/'Data Sheet'!H34)-1,0) -> 0.2338375 | F15: =IFERROR(('Data Sheet'!J34/'Data Sheet'!I34)-1,0) -> 0.025756513 | G15: =IFERROR(('Data Sheet'!K34/'Data Sheet'!J34)-1,0) -> 0.53006384 | K15: =AVERAGE(C15:G15) -> 0.16789379 | L15: 0.124
A17: # | B17: Profitability Ratios
B18: Gross Margin | C18: =IFERROR('Historical FS'!H15,0) -> 0.45426509 | D18: =IFERROR('Historical FS'!I15,0) -> 0.43848102 | E18: =IFERROR('Historical FS'!J15,0) -> 0.45991746 | F18: =IFERROR('Historical FS'!K15,0) -> 0.47497466 | G18: =IFERROR('Historical FS'!L15,0) -> 0.44945073 | K18: =AVERAGE(C18:G18) -> 0.45541779 | L18: -
B19: EBITDA Margin | C19: =IFERROR('Historical FS'!H24,0) -> 0.39875653 | D19: =IFERROR('Historical FS'!I24,0) -> 0.37155645 | E19: =IFERROR('Historical FS'!J24,0) -> 0.39202313 | F19: =IFERROR('Historical FS'!K24,0) -> 0.41980223 | G19: =IFERROR('Historical FS'!L24,0) -> 0.57929362 | K19: =AVERAGE(C19:G19) -> 0.43228639 | L19: -
B20: EBIT Margin | C20: =IFERROR('Data Sheet'!G33/'Data Sheet'!G17,0) -> 0.36534859 | D20: =IFERROR('Data Sheet'!H33/'Data Sheet'!H17,0) -> 0.34298982 | E20: =IFERROR('Data Sheet'!I33/'Data Sheet'!I17,0) -> 0.36651502 | F20: =IFERROR('Data Sheet'!J33/'Data Sheet'!J17,0) -> 0.3974556 | G20: =IFERROR('Data Sheet'!K33/'Data Sheet'!K17,0) -> 0.55743691 | K20: =AVERAGE(C20:G20) -> 0.40594919 | L20: -
B21: EBT Margin | C21: =IFERROR('Historical FS'!H33,0) -> 0.36417171 | D21: =IFERROR('Historical FS'!I33,0) -> 0.34200062 | E21: =IFERROR('Historical FS'!J33,0) -> 0.36541842 | F21: =IFERROR('Historical FS'!K33,0) -> 0.39687988 | G21: =IFERROR('Historical FS'!L33,0) -> 0.55683869 | K21: =AVERAGE(C21:G21) -> 0.40506186 | L21: -
B22: Net Profit Margin | C22: =IFERROR('Historical FS'!H39,0) -> 0.27169251 | D22: =IFERROR('Historical FS'!I39,0) -> 0.25563934 | E22: =IFERROR('Historical FS'!J39,0) -> 0.2746332 | F22: =IFERROR('Historical FS'!K39,0) -> 0.3054728 | G22: =IFERROR('Historical FS'!L39,0) -> 0.46536014 | K22: =AVERAGE(C22:G22) -> 0.3145596 | L22: 0.12
B23: SalesExpenses%Sales | C23: =IFERROR('Historical FS'!H18,0) -> 0.1975767 | D23: =IFERROR('Historical FS'!I18,0) -> 0.1752656 | E23: =IFERROR('Historical FS'!J18,0) -> 0.18047665 | F23: =IFERROR('Historical FS'!K18,0) -> 0.19846414 | G23: =IFERROR('Historical FS'!L18,0) -> 0.19326821 | K23: =AVERAGE(C23:G23) -> 0.18901026 | L23: -
B24: Depreciation%Sales | C24: =IFERROR('Historical FS'!H30,0) -> 0.033407941 | D24: =IFERROR('Historical FS'!I30,0) -> 0.028566628 | E24: =IFERROR('Historical FS'!J30,0) -> 0.025508104 | F24: =IFERROR('Historical FS'!K30,0) -> 0.022346631 | G24: =IFERROR('Historical FS'!L30,0) -> 0.021856705 | K24: =AVERAGE(C24:G24) -> 0.026337202 | L24: -
B25: OperatingIncome%Sales | C25: =C20 -> 0.36534859 | D25: =D20 -> 0.34298982 | E25: =E20 -> 0.36651502 | F25: =F20 -> 0.3974556 | G25: =G20 -> 0.55743691 | K25: =AVERAGE(C25:G25) -> 0.40594919 | L25: -
B26: Return on Capital Employed | C26: =IFERROR(('Historical FS'!H23-'Historical FS'!H29)/SUM('Data Sheet'!G57:G59),0) -> 0.29687699 | D26: =IFERROR(('Historical FS'!I23-'Historical FS'!I29)/SUM('Data Sheet'!H57:H59),0) -> 0.33171927 | E26: =IFERROR(('Historical FS'!J23-'Historical FS'!J29)/SUM('Data Sheet'!I57:I59),0) -> 0.37420679 | F26: =IFERROR(('Historical FS'!K23-'Historical FS'!K29)/SUM('Data Sheet'!J57:J59),0) -> 0.36091131 | G26: =IFERROR(('Historical FS'!L23-'Historical FS'!L29)/SUM('Data Sheet'!K57:K59),0) -> 0.59714506 | K26: =AVERAGE(C26:G26) -> 0.39217188 | L26: -
B27: Retained Earnings% | C27: =IFERROR('Historical FS'!H49,0) -> 0.011277094 | D27: =IFERROR('Historical FS'!I49,0) -> 0.085874917 | E27: =IFERROR('Historical FS'!J49,0) -> 0.010952563 | F27: =IFERROR('Historical FS'!K49,0) -> 0.17275494 | G27: =IFERROR('Historical FS'!L49,0) -> 0.48769017 | K27: =AVERAGE(C27:G27) -> 0.15370994 | L27: -
B28: Return on Equity% | C28: =IFERROR('Historical FS'!H38/SUM('Data Sheet'!G57:G58),0) -> 0.22176421 | D28: =IFERROR('Historical FS'!I38/SUM('Data Sheet'!H57:H58),0) -> 0.24822654 | E28: =IFERROR('Historical FS'!J38/SUM('Data Sheet'!I57:I58),0) -> 0.28163758 | F28: =IFERROR('Historical FS'!K38/SUM('Data Sheet'!J57:J58),0) -> 0.27851558 | G28: =IFERROR('Historical FS'!L38/SUM('Data Sheet'!K57:K58),0) -> 0.50053484 | K28: =AVERAGE(C28:G28) -> 0.30613575 | L28: 0.35
A30: # | B30: Solvency Ratios
B31: Interest Coverage Ratio | C31: =IFERROR(('Historical FS'!H23-'Historical FS'!H29)/'Historical FS'!H26,0) -> 310.43885 | D31: =IFERROR(('Historical FS'!I23-'Historical FS'!I29)/'Historical FS'!I26,0) -> 346.73212 | E31: =IFERROR(('Historical FS'!J23-'Historical FS'!J29)/'Historical FS'!J26,0) -> 334.22772 | F31: =IFERROR(('Historical FS'!K23-'Historical FS'!K29)/'Historical FS'!K26,0) -> 690.35873 | G31: =IFERROR(('Historical FS'!L23-'Historical FS'!L29)/'Historical FS'!L26,0) -> 931.82446 | K31: =AVERAGE(C31:G31) -> 522.71638 | L31: 10
A33: # | B33: Efficiency Ratios
B34: Debtor Turnover Ratio | C34: =IFERROR('Historical FS'!H8/'Historical FS'!H64,0) -> 19.689591 | D34: =IFERROR('Historical FS'!I8/'Historical FS'!I64,0) -> 24.633226 | E34: =IFERROR('Historical FS'!J8/'Historical FS'!J64,0) -> 23.990173 | F34: =IFERROR('Historical FS'!K8/'Historical FS'!K64,0) -> 16.874063 | G34: =IFERROR('Historical FS'!L8/'Historical FS'!L64,0) -> 15.959451 | K34: =AVERAGE(C34:G34) -> 20.229301 | L34: 45.62
B35: Creditor Turnover Ratio | C35: =IFERROR('Historical FS'!H8/'Historical FS'!H55,0) -> 3.7479256 | D35: =IFERROR('Historical FS'!I8/'Historical FS'!I55,0) -> 4.1849768 | E35: =IFERROR('Historical FS'!J8/'Historical FS'!J55,0) -> 4.3323459 | F35: =IFERROR('Historical FS'!K8/'Historical FS'!K55,0) -> 4.0093121 | G35: =IFERROR('Historical FS'!L8/'Historical FS'!L55,0) -> 4.2584165 | K35: =AVERAGE(C35:G35) -> 4.1065954 | L35: 5.04
B36: Inventory Turnover | C36: =IFERROR('Historical FS'!H11/'Historical FS'!H65,0) -> 2.5854666 | D36: =IFERROR('Historical FS'!I11/'Historical FS'!I65,0) -> 3.1344431 | E36: =IFERROR('Historical FS'!J11/'Historical FS'!J65,0) -> 3.253896 | F36: =IFERROR('Historical FS'!K11/'Historical FS'!K65,0) -> 2.5200517 | G36: =IFERROR('Historical FS'!L11/'Historical FS'!L65,0) -> 2.6518977 | K36: =AVERAGE(C36:G36) -> 2.829151 | L36: 3
B37: Fixed Asset Turnover | C37: =IFERROR('Historical FS'!H8/'Historical FS'!H58,0) -> 2.1141916 | D37: =IFERROR('Historical FS'!I8/'Historical FS'!I58,0) -> 2.5027058 | E37: =IFERROR('Historical FS'!J8/'Historical FS'!J58,0) -> 2.743348 | F37: =IFERROR('Historical FS'!K8/'Historical FS'!K58,0) -> 2.4418189 | G37: =IFERROR('Historical FS'!L8/'Historical FS'!L58,0) -> 3.4308292 | K37: =AVERAGE(C37:G37) -> 2.6465787 | L37: -
B38: CFO/Sales | C38: =IFERROR('Historical FS'!H$75/'Historical FS'!H8,0) -> 0.25431625 | D38: =IFERROR('Historical FS'!I$75/'Historical FS'!I8,0) -> 0.26013076 | E38: =IFERROR('Historical FS'!J$75/'Historical FS'!J8,0) -> 0.26618455 | F38: =IFERROR('Historical FS'!K$75/'Historical FS'!K8,0) -> 0.2528834 | G38: =IFERROR('Historical FS'!L$75/'Historical FS'!L8,0) -> 0.2340183 | K38: =AVERAGE(C38:G38) -> 0.25350665 | L38: -
B39: Capital Turnover Ratio | C39: =IFERROR('Historical FS'!H8/SUM('Historical FS'!H52:H53),0) -> 0.81623233 | D39: =IFERROR('Historical FS'!I8/SUM('Historical FS'!I52:I53),0) -> 0.97100291 | E39: =IFERROR('Historical FS'!J8/SUM('Historical FS'!J52:J53),0) -> 1.0255045 | F39: =IFERROR('Historical FS'!K8/SUM('Historical FS'!K52:K53),0) -> 0.91175245 | G39: =IFERROR('Historical FS'!L8/SUM('Historical FS'!L52:L53),0) -> 1.075586 | K39: =AVERAGE(C39:G39) -> 0.96001563 | L39: -
A41: # | B41: Working Capital Efficiency Ratios
B42: Debtor Days | C42: =365/C34 -> 18.537714 | D42: =365/D34 -> 14.817385 | E42: =365/E34 -> 15.214563 | F42: =365/F34 -> 21.630831 | G42: =365/G34 -> 22.870462 | K42: =AVERAGE(C42:G42) -> 18.614191 | L42: =365/L34 -> 8.0008768
B43: Payable Days | C43: =365/C35 -> 97.387204 | D43: =365/D35 -> 87.216733 | E43: =365/E35 -> 84.249966 | F43: =365/F35 -> 91.038061 | G43: =365/G35 -> 85.712611 | K43: =AVERAGE(C43:G43) -> 89.120915 | L43: =365/L35 -> 72.420635
B44: Inventory Days | C44: =365/C36 -> 141.17374 | D44: =365/D36 -> 116.44812 | E44: =365/E36 -> 112.17322 | F44: =365/F36 -> 144.8383 | G44: =365/G36 -> 137.63728 | K44: =AVERAGE(C44:G44) -> 130.45413 | L44: =365/L36 -> 121.66667
B45: Cash Conversion Cycle | C45: =(C42+C44)-C43 -> 62.324253 | D45: =(D42+D44)-D43 -> 44.04877 | E45: =(E42+E44)-E43 -> 43.13782 | F45: =(F42+F44)-F43 -> 75.431065 | G45: =(G42+G44)-G43 -> 74.795134 | K45: =AVERAGE(C45:G45) -> 59.947408 | L45: =(L42+L44)-L43 -> 57.246909
A47: # | B47: Liquidity Ratios
B48: CFO/Total Assets | C48: =IFERROR('Historical FS'!H$75/'Historical FS'!H69,0) -> 0.16983244 | D48: =IFERROR('Historical FS'!I$75/'Historical FS'!I69,0) -> 0.20435652 | E48: =IFERROR('Historical FS'!J$75/'Historical FS'!J69,0) -> 0.2199387 | F48: =IFERROR('Historical FS'!K$75/'Historical FS'!K69,0) -> 0.18722743 | G48: =IFERROR('Historical FS'!L$75/'Historical FS'!L69,0) -> 0.20030113 | K48: =AVERAGE(C48:G48) -> 0.19633124 | L48: -
...

Sheet WACC
B2: Calculation of WACC
B3: ='Data Sheet'!B1 -> ITC LTD
B5: All figures are in INR unless stated otherwise.
B7: 1. Peer Comps
G8: Debt/ | H8: Debt/ | I8: Levered | J8: Unlevered
B9: Name | C9: Country | D9: Total Debt | E9: Total Equity | F9: Tax Rate 1 | G9: Equity | H9: Capital | I9: Beta 2 | J9: Beta 3
B11: ='WACC Data'!C4 -> ITC | C11: India | D11: ='WACC Data'!D4 -> 285 | E11: ='WACC Data'!E4 -> 519668 | F11: 0.3 | G11: =D11/E11 -> 0.00054842707 | H11: =D11/SUM(D11:E11) -> 0.00054812647 | I11: ='Beta - Regression'!J7 -> 0.49821386 | J11: =I11/1+(1-F11)*G11 -> 0.49859776
B12: ='WACC Data'!C5 -> Godfrey Phillips | C12: India | D12: ='WACC Data'!D5 -> 179 | E12: ='WACC Data'!E5 -> 45635 | F12: 0.3 | G12: =D12/E12 -> 0.003922428 | H12: =D12/SUM(D12:E12) -> 0.0039071026 | I12: 1.22 | J12: =I12/1+(1-F12)*G12 -> 1.2227457
B13: ='WACC Data'!C6 -> VST Industries | C13: India | D13: ='WACC Data'!D6 -> 0 | E13: ='WACC Data'!E6 -> 4791 | F13: 0.3 | G13: =D13/E13 -> 0 | H13: =D13/SUM(D13:E13) -> 0 | I13: 0.88 | J13: =I13/1+(1-F13)*G13 -> 0.88
B14: ='WACC Data'!C7 -> NTC Industries | C14: India | D14: ='WACC Data'!D7 -> 77.1 | E14: ='WACC Data'!E7 -> 249 | F14: 0.3 | G14: =D14/E14 -> 0.30963855 | H14: =D14/SUM(D14:E14) -> 0.23643054 | I14: 0.88 | J14: =I14/(1+(1-F14)*G14) -> 0.72323992
B15: ='WACC Data'!C8 -> Indian Wood Prod | C15: India | D15: ='WACC Data'!D8 -> 79.9 | E15: ='WACC Data'!E8 -> 253 | F15: 0.3 | G15: =D15/E15 -> 0.31581028 | H15: =D15/SUM(D15:E15) -> 0.24001202 | I15: 0.53 | J15: =I15/(1+(1-F15)*G15) -> 0.43404655
B16: ='WACC Data'!C9 -> Elitecon Inter. | C16: India | D16: ='WACC Data'!D9 -> 2.51 | E16: ='WACC Data'!E9 -> 32537 | F16: 0.3 | G16: =D16/E16 -> 7.7142945e-05 | H16: =D16/SUM(D16:E16) -> 7.7136994e-05 | I16: 0.2 | J16: =I16/(1+(1-F16)*G16) -> 0.1999892
E18: Average | F18: =AVERAGE(F11:F16) -> 0.3 | G18: =AVERAGE(G11:G16) -> 0.10499947 | H18: =AVERAGE(H11:H16) -> 0.080162487 | I18: =AVERAGE(I11:I16) -> 0.70136898 | J18: =AVERAGE(J11:J16) -> 0.65976986
E19: Median | F19: =MEDIAN(F11:F16) -> 0.3 | G19: =MEDIAN(G11:G16) -> 0.0022354275 | H19: =MEDIAN(H11:H16) -> 0.0022276145 | I19: =MEDIAN(I11:I16) -> 0.705 | J19: =MEDIAN(J11:J16) -> 0.61091884
B21: 2. Cost of Debt | G21: 4. Levered Beta
B23: Pre-tax Cost of Debt | E23: ='Data Sheet'!K27/'Data Sheet'!K59 -> 0.15836086 | G23: Comps Median Unlevered Beta | J23: =J19 -> 0.61091884
B24: Tax Rate | E24: 0.3 | G24: Target Debt/ Equity | J24: =E35 -> 0.08714853
B25: After Tax Cost of Debt | E25: =E23*(1-E24) -> 0.1108526 | G25: Tax Rate | J25: =F11 -> 0.3
G26: Levered Beta 4 | J26: =J23*(1+(1-J25)*J24) -> 0.64818732
B28: 3. Capital Structure | G28: 5. Cost of Equity
C30: Current | D30: Current % | E30: Target % | G30: Risk Free Rate | J30: 0.0649
B31: Total Debt | C31: =D11 -> 285 | D31: =C31/C33 -> 0.00054812647 | E31: =H18 -> 0.080162487 | G31: Equity Risk Premium | J31: =Rm!F5-WACC!J30 -> 0.101448
B32: Market Capitalization | C32: =E11 -> 519668 | D32: =C32/C33 -> 0.99945187 | E32: =1-E31 -> 0.91983751 | G32: Levered Beta | J32: =J26 -> 0.64818732
B33: Total Capitalization | C33: =SUM(C31:C32) -> 519953 | D33: =SUM(D31:D32) -> 1 | E33: =SUM(E31:E32) -> 1 | G33: Cost of Equity | J33: =J30+(J31*J32) -> 0.13065731
B35: Debt / Equity | D35: =D31/D32 -> 0.00054842707 | E35: =E31/E32 -> 0.08714853 | G35: 6. Weighted Average Cost of Capital
B37: 1. Tax Rate considered as Marginal Tax Rate for the country | I37: Total Cost | J37: Total Weight
B38: 2. Levered Beta is based on 5 year monthly data | G38: Debt Capital | I38: =E25 -> 0.1108526 | J38: =E31 -> 0.080162487
B39: 3. Unlevered Beta = Levered Beta/(1+(1-Tax Rate) x Debt/Equity) | G39: Equity Capital | I39: =J33 -> 0.13065731 | J39: =E32 -> 0.91983751
B40: 4. Levered Beta = Unlevered Beta*(1+(1-Tax Rate) x Debt/Equity) | G40: Weighted Average Cost of Capital | J40: =SUMPRODUCT(I38:I39,J38:J39) -> 0.12906971

Sheet Intrinsic Growth
B2: Calculation of Intrinsic Growth
B3: ='[2]Data Sheet'!B1 -> ITC LTD
A5: # | B5: Calculation of ROIC | G5: ='RAW FSn'!J4 -> 44256 | H5: ='RAW FSn'!K4 -> 44621 | I5: ='RAW FSn'!L4 -> 44986 | J5: ='RAW FSn'!M4 -> 45352 | K5: ='RAW FSn'!N4 -> 45717
B7: Current Assets
B8: ='RAW FSn'!B36 -> Other Assets | G8: ='RAW FSn'!J37 -> 10397 | H8: ='RAW FSn'!K37 -> 10864 | I8: ='RAW FSn'!L37 -> 11771 | J8: ='RAW FSn'!M37 -> 14153 | K8: ='RAW FSn'!N37 -> 15638
B9: ='RAW FSn'!B37 -> Inventories | G9: ='RAW FSn'!J38 -> 2502 | H9: ='RAW FSn'!K38 -> 2462 | I9: ='RAW FSn'!L38 -> 2956 | J9: ='RAW FSn'!M38 -> 4026 | K9: ='RAW FSn'!N38 -> 4720
B10: ='RAW FSn'!B40 -> Loans n Advances | G10: ='RAW FSn'!J41 -> 4015 | H10: ='RAW FSn'!K41 -> 6906 | I10: ='RAW FSn'!L41 -> 7941 | J10: ='RAW FSn'!M41 -> 4531 | K10: ='RAW FSn'!N41 -> 5858
B11: Total Current Assets | G11: =SUM(G8:G10) -> 16914 | H11: =SUM(H8:H10) -> 20232 | I11: =SUM(I8:I10) -> 22668 | J11: =SUM(J8:J10) -> 22710 | K11: =SUM(K8:K10) -> 26216
B13: Current Liabilities
B14: ='RAW FSn'!B14 -> Trade Payables | G14: ='RAW FSn'!J14 -> 4319 | H14: ='RAW FSn'!K14 -> 4417 | I14: ='RAW FSn'!L14 -> 4659 | J14: ='RAW FSn'!M14 -> 4798 | K14: ='RAW FSn'!N14 -> 4807
B15: ='RAW FSn'!B15 -> Advance from Customers | G15: ='RAW FSn'!J15 -> 811 | H15: ='RAW FSn'!K15 -> 1278 | I15: ='RAW FSn'!L15 -> 1295 | J15: ='RAW FSn'!M15 -> 886 | K15: ='RAW FSn'!N15 -> 1264
B16: ='RAW FSn'!B16 -> Other liability items | G16: ='RAW FSn'!J16 -> 7666 | H16: ='RAW FSn'!K16 -> 8429 | I16: ='RAW FSn'!L16 -> 10032 | J16: ='RAW FSn'!M16 -> 10877 | K16: ='RAW FSn'!N16 -> 11249
B17: Total Current Liabilities | G17: =SUM(G14:G16) -> 12796 | H17: =SUM(H14:H16) -> 14124 | I17: =SUM(I14:I16) -> 15986 | J17: =SUM(J14:J16) -> 16561 | K17: =SUM(K14:K16) -> 17320
A19: # | B19: Net Working Capital | G19: =G11-G17 -> 4118 | H19: =H11-H17 -> 6108 | I19: =I11-I17 -> 6682 | J19: =J11-J17 -> 6149 | K19: =K11-K17 -> 8896
B21: Non Current Assets
B22: ='RAW FSn'!B20 -> Land | G22: ='RAW FSn'!J20 -> 2889 | H22: ='RAW FSn'!K20 -> 2829 | I22: ='RAW FSn'!L20 -> 2830 | J22: ='RAW FSn'!M20 -> 2865 | K22: ='RAW FSn'!N20 -> 1588
B23: ='RAW FSn'!B21 -> Building | G23: ='RAW FSn'!J21 -> 8387 | H23: ='RAW FSn'!K21 -> 9100 | I23: ='RAW FSn'!L21 -> 9789 | J23: ='RAW FSn'!M21 -> 10944 | K23: ='RAW FSn'!N21 -> 7550
B24: ='RAW FSn'!B22 -> Plant Machinery | G24: ='RAW FSn'!J22 -> 15307 | H24: ='RAW FSn'!K22 -> 16912 | I24: ='RAW FSn'!L22 -> 18480 | J24: ='RAW FSn'!M22 -> 20718 | K24: ='RAW FSn'!N22 -> 19423
B25: ='RAW FSn'!B23 -> Equipments | G25: ='RAW FSn'!J23 -> 41 | H25: ='RAW FSn'!K23 -> 44 | I25: ='RAW FSn'!L23 -> 44 | J25: ='RAW FSn'!M23 -> 53 | K25: ='RAW FSn'!N23 -> 63
B26: ='RAW FSn'!B24 -> Furniture n fittings | G26: ='RAW FSn'!J24 -> 833 | H26: ='RAW FSn'!K24 -> 907 | I26: ='RAW FSn'!L24 -> 1000 | J26: ='RAW FSn'!M24 -> 1068 | K26: ='RAW FSn'!N24 -> 282
B27: ='RAW FSn'!B25 -> Railway sidings | G27: ='RAW FSn'!J25 -> 2 | H27: ='RAW FSn'!K25 -> 2 | I27: ='RAW FSn'!L25 -> 2 | J27: ='RAW FSn'!M25 -> 2 | K27: ='RAW FSn'!N25 -> 2
B28: ='RAW FSn'!B26 -> Vehicles | G28: ='RAW FSn'!J26 -> 180 | H28: ='RAW FSn'!K26 -> 179 | I28: ='RAW FSn'!L26 -> 189 | J28: ='RAW FSn'!M26 -> 192 | K28: ='RAW FSn'!N26 -> 141
B29: ='RAW FSn'!B27 -> Intangible Assets | G29: ='RAW FSn'!J27 -> 2734 | H29: ='RAW FSn'!K27 -> 2744 | I29: ='RAW FSn'!L27 -> 3490 | J29: ='RAW FSn'!M27 -> 3505 | K29: ='RAW FSn'!N27 -> 3622
B30: ='RAW FSn'!B28 -> Other fixed assets | G30: ='RAW FSn'!J28 -> 716 | H30: ='RAW FSn'!K28 -> 719 | I30: ='RAW FSn'!L28 -> 786 | J30: ='RAW FSn'!M28 -> 841 | K30: ='RAW FSn'!N28 -> 967
B32: Gross Block | G32: =SUM(G22:G30) -> 31089 | H32: =SUM(H22:H30) -> 33436 | I32: =SUM(I22:I30) -> 36610 | J32: =SUM(J22:J30) -> 40188 | K32: =SUM(K22:K30) -> 33638
B33: Accumulated Depreciation | G33: =-'RAW FSn'!J30 -> -7790 | H33: =-'RAW FSn'!K30 -> -9204 | I33: =-'RAW FSn'!L30 -> -10757 | J33: =-'RAW FSn'!M30 -> -12368 | K33: =-'RAW FSn'!N30 -> -11683
A34: # | B34: Net Non Current Assets | G34: =SUM(G32:G33) -> 23299 | H34: =SUM(H32:H33) -> 24232 | I34: =SUM(I32:I33) -> 25853 | J34: =SUM(J32:J33) -> 27820 | K34: =SUM(K32:K33) -> 21955
A36: # | B36: Invested Capital | G36: =G34+G19 -> 27417 | H36: =H34+H19 -> 30340 | I36: =I34+I19 -> 32535 | J36: =J34+J19 -> 33969 | K36: =K34+K19 -> 30851
B37: EBIT | G37: ='Data Sheet'!G33 -> 17996.14 | H37: ='Data Sheet'!H33 -> 20800.46 | I37: ='Data Sheet'!I33 -> 25992.89 | J37: ='Data Sheet'!J33 -> 26999.93 | K37: ='Data Sheet'!K33 -> 41988.01
B38: Tax Rate | G38: 0.3 | H38: 0.3 | I38: 0.3 | J38: 0.3 | K38: 0.3
A40: # | B40: ROIC | G40: =(G37*(1-G38))/G36 -> 0.45947033 | H40: =(H37*(1-H38))/H36 -> 0.47990514 | I40: =(I37*(1-I38))/I36 -> 0.5592446 | J40: =(J37*(1-J38))/J36 -> 0.55638821 | K40: =(K37*(1-K38))/K36 -> 0.95269544
A42: # | B42: Calculation of Reinvestment Rate | G42: =G5 -> 44256 | H42: =H5 -> 44621 | I42: =I5 -> 44986 | J42: =J5 -> 45352 | K42: =K5 -> 45717
B44: CAPEX | G44: =-SUM('RAW FSn'!J53:J54) -> 1834 | H44: =-SUM('RAW FSn'!K53:K54) -> 2009 | I44: =-SUM('RAW FSn'!L53:L54) -> 2694 | J44: =-SUM('RAW FSn'!M53:M54) -> 3456 | K44: =-SUM('RAW FSn'!N53:N54) -> 2104
B45: Change in Working Capital | H45: =H19-G19 -> 1990 | I45: =I19-H19 -> 574 | J45: =J19-I19 -> -533 | K45: =K19-J19 -> 2747
B46: Depriciation | H46: ='Data Sheet'!H26 -> 1732.41 | I46: ='Data Sheet'!I26 -> 1809.01 | J46: ='Data Sheet'!J26 -> 1518.05 | K46: ='Data Sheet'!K26 -> 1646.32
B48: EBIT | G48: =G37 -> 17996.14 | H48: =H37 -> 20800.46 | I48: =I37 -> 25992.89 | J48: =J37 -> 26999.93 | K48: =K37 -> 41988.01
B49: Tax Rate | G49: 0.3 | H49: 0.3 | I49: 0.3 | J49: 0.3 | K49: 0.3
B50: EBIT(1-T) | G50: =G48*(1-G49) -> 12597.298 | H50: =H48*(1-H49) -> 14560.322 | I50: =I48*(1-I49) -> 18195.023 | J50: =J48*(1-J49) -> 18899.951 | K50: =K48*(1-K49) -> 29391.607
B52: Net CAPEX/Reinvestment | H52: =SUM(H44:H45)-H46 -> 2266.59 | I52: =SUM(I44:I45)-I46 -> 1458.99 | J52: =SUM(J44:J45)-J46 -> 1404.95 | K52: =SUM(K44:K45)-K46 -> 3204.68
B54: Reinvestment Rate | H54: =H52/H50 -> 0.15566895 | I54: =I52/I50 -> 0.080186214 | J54: =J52/J50 -> 0.074336172 | K54: =K52/K50 -> 0.10903385
...

Sheet DCF
B2: Discounted Cash Flow Model
B3: ='[2]Data Sheet'!B1 -> ITC LTD
A5: # | B5: Calculation of PV of FCFF | F5: ='Intrinsic Growth'!K5 -> 45717 | G5: =F5+365 -> 46082 | H5: =G5+366 -> 46448 | I5: =H5+365 -> 46813 | J5: =I5+365 -> 47178 | K5: =J5+365 -> 47543
B7: Growth Rate | F7: =D19 -> 0.066196463 | G7: =F7-(($F$7-$K$7)/4) -> 0.059647348 | H7: =G7-(($F$7-$K$7)/4) -> 0.053098232 | I7: =H7-(($F$7-$K$7)/4) -> 0.046549116 | J7: =I7-(($F$7-$K$7)/4) -> 0.04 | K7: =D18 -> 0.04
B8: EBIT | F8: ='Data Sheet'!K33 -> 41988.01 | G8: =F8*(1+G7) -> 44492.483 | H8: =G8*(1+H7) -> 46854.956 | I8: =H8*(1+I7) -> 49036.012 | J8: =I8*(1+J7) -> 50997.453 | K8: =J8*(1+K7) -> 53037.351
B9: Tax Rate | F9: 0.3 | G9: =F9 -> 0.3 | H9: =G9 -> 0.3 | I9: =H9 -> 0.3 | J9: =I9 -> 0.3 | K9: =J9 -> 0.3
B10: EBIT(1-T) | F10: =F8*(1-F9) -> 29391.607 | G10: =G8*(1-G9) -> 31144.738 | H10: =H8*(1-H9) -> 32798.469 | I10: =I8*(1-I9) -> 34325.209 | J10: =J8*(1-J9) -> 35698.217 | K10: =K8*(1-K9) -> 37126.146
B11: Less: Reinvestment Rate | F11: ='Intrinsic Growth'!C57 -> 0.094610031 | G11: =F11+(($K$11-$F$11)/4) -> 0.15095752 | H11: =G11+(($K$11-$F$11)/4) -> 0.20730502 | I11: =H11+(($K$11-$F$11)/4) -> 0.26365251 | J11: =I11+(($K$11-$F$11)/4) -> 0.32 | K11: 0.32
B12: Free Cash Flow to Firm (FCFF) | F12: =F10*(1-F11) -> 26610.866 | G12: =G10*(1-G11) -> 26443.206 | H12: =H10*(1-H11) -> 25999.182 | I12: =I10*(1-I11) -> 25275.281 | J12: =J10*(1-J11) -> 24274.788 | K12: =K10*(1-K11) -> 25245.779
B13: Mid Year Convention | G13: 0.5 | H13: =+G13+1 -> 1.5 | I13: =+H13+1 -> 2.5 | J13: =+I13+1 -> 3.5 | K13: =+J13+1 -> 4.5
B14: Discounting Factor | G14: =1/(1+$D$21)^G13 -> 0.94110834 | H14: =1/(1+$D$21)^H13 -> 0.83352545 | I14: =1/(1+$D$21)^I13 -> 0.73824091 | J14: =1/(1+$D$21)^J13 -> 0.65384883 | K14: =1/(1+$D$21)^K13 -> 0.57910403
B16: PV of FCFF | G16: =G12*G14 -> 24885.921 | H16: =H12*H14 -> 21670.98 | I16: =I12*I14 -> 18659.247 | J16: =J12*J14 -> 15872.041 | K16: =K12*K14 -> 14619.933
B18: Expected Sector EBIT Growth | D18: 0.04
B19: Intrinsic Growth | D19: ='Intrinsic Growth'!C66 -> 0.066196463 | G19: Sanity Check for Terminal Growth Rate > Sector Growth Rate
B20: Terminal Growth Rate (GDP) | D20: 0.065 | G20: =IF(D19>D20,"Pass","Recheck") -> Pass
B21: WACC | D21: =WACC!J40 -> 0.12906971
A23: # | B23: Calculation of Terminal Value of FCFF | G23: Sensitivity Analysis - Share Price
G24: =D43 -> 268.92545 | H24: 0.1 | I24: =D21 -> 0.12906971 | J24: 0.14 | K24: 0.16 | L24: WACC
B25: FCFF (n+1) | D25: =K12*(1+D18) -> 26255.61 | G25: 0.04 | H25: 281.7801 | I25: 215.73205 | J25: 200.8315 | K25: 180.59436
B26: WACC | D26: =D21 -> 0.12906971 | G26: 0.065 | H26: 426.33116 | I26: 268.92545 | J26: 241.3058 | K26: 207.22218
B27: Terminal Growth Rate | D27: =D20 -> 0.065 | G27: 0.07 | H27: 484.15158 | I27: 284.96724 | J27: 252.86989 | K27: 214.32294
G28: 0.075 | H28: 565.10018 | I28: 303.97591 | J28: 266.21306 | K28: 222.25907
B29: Terminal Value | D29: =D25/(D26-D27) -> 409797.53 | G29: 0.08 | H29: 686.52307 | I29: 326.85838 | J29: 281.7801 | K29: 231.18723
G30: Growth Rate
A32: # | B32: Calculation of Equity Value per Share
B34: PV of FCFF | D34: =SUM(G16:K16) -> 95708.122
B35: PV of Terminal Value | D35: =D29*K14 -> 237315.4
B36: Value of Operating Assets | D36: =SUM(D34:D35) -> 333023.53
B37: (Also the Enterprise Value)
B38: Add: Cash | D38: ='Data Sheet'!K69 -> 4012.36
B39: Less: Debt | D39: =SUM('RAW FSn'!N8:N10) -> 284
B40: Value of Equity | D40: =D36+D38-D39 -> 336751.89
B41: No of Shares | D41: ='Data Sheet'!B6 -> 1252.2128
B43: Equity Value per Share | D43: =D40/D41 -> 268.92545
B45: Share price | D45: 407
B46: Discount/Premium | D46: =D45/D43 -> 1.5134306
B47: Valuation | D47: =IF(D46>1,"Overvalued","Undervalued") -> Overvalued

Sheet Football Field
B2: Football Field Analysis
B3: ='Data Sheet'!B1 -> ITC LTD
B4: Data is from Comparables Valuation of ITC and BBB Scenario Analysis Tab
J6: Football Field Analysis - Data
L7: OpenLow | M7: Low | N7: OpenHigh | O7: High
J8: Comps | L8: 365.6 | M8: =L8 -> 365.6 | N8: 534.3 | O8: =N8 -> 534.3
J9: DCF Bear | L9: =DCF!K25 -> 180.59436 | M9: =L9 -> 180.59436 | N9: =DCF!H25 -> 281.7801 | O9: =N9 -> 281.7801
J10: DCF Base | L10: =DCF!K26 -> 207.22218 | M10: =L10 -> 207.22218 | N10: =DCF!H26 -> 426.33116 | O10: =N10 -> 426.33116
J11: DCF Bull | L11: =DCF!K29 -> 231.18723 | M11: =L11 -> 231.18723 | N11: =DCF!H29 -> 686.52307 | O11: =N11 -> 686.52307
J12: 52W H/L | L12: 390 | M12: =L12 -> 390 | N12: 495 | O12: =N12 -> 495
C21: Current Market Price

Sheet Data

Sheet Data Sheet
A1: COMPANY NAME | B1: ITC LTD | E1: =IF(B2<>B3, "A NEW VERSION OF THE WORKSHEET IS AVAILABLE", "")
A2: LATEST VERSION | B2: 2.1 | E2: PLEASE DO NOT MAKE ANY CHANGES TO THIS SHEET
A3: CURRENT VERSION | B3: 2.1
A5: META
A6: Number of shares | B6: =IF(B9>0, B9/B8, 0) -> 1252.2128
A7: Face Value | B7: 1
A8: Current Price | B8: 415
A9: Market Capitalization | B9: 519668.31
A15: PROFIT & LOSS
A16: Report Date | B16: 42460 | C16: 42825 | D16: 43190 | E16: 43555 | F16: 43921 | G16: 44286 | H16: 44651 | I16: 45016 | J16: 45382 | K16: 45747
A17: Sales | B17: 39192.1 | C17: 42767.6 | D17: 43448.94 | E17: 48339.58 | F17: 49387.7 | G17: 49257.45 | H17: 60644.54 | I17: 70919.03 | J17: 67931.94 | K17: 75323.34
A18: Raw Material Cost | B18: 13763.88 | C18: 15456.59 | D18: 14827.72 | E18: 17623.52 | F18: 18048.6 | G18: 20776.71 | H18: 27071.07 | I18: 29364.36 | J18: 27348.57 | K18: 32704.37
A19: Change in Inventory | B19: 195.38 | C19: -592.57 | D19: -1027.76 | E19: 203.19 | F19: 703.13 | G19: 645.27 | H19: 686 | I19: 358.59 | J19: 367.77 | K19: 725.65
A20: Power and Fuel | B20: 571.88 | C20: 584.33 | D20: 653.5 | E20: 746.73 | F20: 780.85 | G20: 699.56 | H20: 889.77 | I20: 1232.34 | J20: 952.9 | K20: 975.35
A21: Other Mfr. Exp | B21: 1581.59 | C21: 1683.9 | D21: 1697.62 | E21: 1871.01 | F21: 1908.29 | G21: 1587.18 | H21: 1887.67 | I21: 2327.8 | J21: 2183.76 | K21: 2345.36
A22: Employee Cost | B22: 3440.97 | C22: 3631.73 | D22: 3760.9 | E22: 4177.88 | F22: 4295.79 | G22: 4463.33 | H22: 4890.55 | I22: 5736.22 | J22: 5548.53 | K22: 6169.78
A23: Selling and admin | B23: 4261.78 | C23: 4179.74 | D23: 3954.87 | E23: 4546.39 | F23: 4488.63 | G23: 4236.77 | H23: 4858.38 | I23: 5604.08 | J23: 5312.45 | K23: 5793.29
A24: Other Expenses | B24: 1235.89 | C24: 1169.23 | D24: 1005.98 | E24: 1039.85 | F24: 1225.13 | G24: 1074.39 | H24: 1109.95 | I24: 1308.56 | J24: 1765.97 | K24: 2221.39
A25: Other Income | B25: 1483.11 | C25: 1758.63 | D25: 2239.81 | E25: 2080.44 | F25: 2417.32 | G25: 2576.95 | H25: 1909.72 | I25: 2097.64 | J25: 3330.45 | K25: 17794.88
A26: Depreciation | B26: 1077.4 | C26: 1152.79 | D26: 1236.28 | E26: 1396.61 | F26: 1644.91 | G26: 1645.59 | H26: 1732.41 | I26: 1809.01 | J26: 1518.05 | K26: 1646.32
A27: Interest | B27: 78.13 | C27: 49.03 | D27: 115.01 | E27: 71.4 | F27: 81.38 | G27: 57.97 | H27: 59.99 | I27: 77.77 | J27: 39.11 | K27: 45.06
... A31: Dividend Amount | B31: 6840.12 | C31: 5770.02 | D31: 6285.21 | E31: 7048.7 | F31: 12476.58 | G31: 13231.96 | H31: 14171.8 | I31: 19263.4 | J31: 17166.46 | K31: 17957.73
A33: EBIT | B33: =B28+B27 -> 14937.2 | C33: =C28+C27 -> 16075.35 | D33: =D28+D27 -> 17524.12 | E33: =E28+E27 -> 19221.22 | F33: =F28+F27 -> 20115.95 | G33: =G28+G27 -> 17996.14 | H33: =H28+H27 -> 20800.46 | I33: =I28+I27 -> 25992.89 | ... K33: =K28+K27 -> 41988.01
A34: EBITDA | B34: =B33+B26 -> 16014.6 | C34: =C33+C26 -> 17228.14 | D34: =D33+D26 -> 18760.4 | E34: =E33+E26 -> 20617.83 | F34: =F33+F26 -> 21760.86 | G34: =G33+G26 -> 19641.73 | H34: =H33+H26 -> 22532.87 | I34: =I33+I26 -> 27801.9 | ... K34: =K33+K26 -> 43634.33
A40: Quarters
